[2013-07-31 12:28:03,080] The process is done normally.
[2013-07-31 14:04:20,593] The process is done normally.
[2013-07-31 16:04:21,182] The process is done normally.
[2013-07-31 18:04:21,295] The process is done normally.
[2013-07-31 20:04:20,859] The process is done normally.
[2013-07-31 22:04:21,942] The process is done normally.
[2013-08-01 00:01:04,186] The process is done normally.
[2013-08-01 02:01:04,257] The process is done normally.
[2013-08-01 04:01:05,072] The process is done normally.
[2013-08-01 06:01:05,025] The process is done normally.
[2013-08-01 08:01:04,543] The process is done normally.
[2013-08-01 10:01:04,367] The process is done normally.
[2013-08-15 04:01:02,080]CRITICAL: The process is terminated with an exception.
Traceback (most recent call last):
  File "/home/cdnlab-gnp/gnp-deploy/obtain_ipaddr.py", line 170, in <module>
    autocommit=True)
  File "/usr/lib/python2.6/site-packages/mysql/connector/__init__.py", line 44, in Connect
    return MySQLConnection(*args, **kwargs)
  File "/usr/lib/python2.6/site-packages/mysql/connector/connection.py", line 108, in __init__
    self.connect(**kwargs)
  File "/usr/lib/python2.6/site-packages/mysql/connector/connection.py", line 356, in connect
    self._open_connection()
  File "/usr/lib/python2.6/site-packages/mysql/connector/connection.py", line 319, in _open_connection
    self._socket.open_connection()
  File "/usr/lib/python2.6/site-packages/mysql/connector/network.py", line 393, in open_connection
    errno=2003, values=(self.server_host, msg))
InterfaceError: 2003: Can't connect to MySQL server on 'localhost' (111)
[2013-08-15 05:01:02,058]CRITICAL: The process is terminated with an exception.
Traceback (most recent call last):
  File "/home/cdnlab-gnp/gnp-deploy/obtain_ipaddr.py", line 170, in <module>
    autocommit=True)
  File "/usr/lib/python2.6/site-packages/mysql/connector/__init__.py", line 44, in Connect
    return MySQLConnection(*args, **kwargs)
  File "/usr/lib/python2.6/site-packages/mysql/connector/connection.py", line 108, in __init__
    self.connect(**kwargs)
  File "/usr/lib/python2.6/site-packages/mysql/connector/connection.py", line 356, in connect
    self._open_connection()
  File "/usr/lib/python2.6/site-packages/mysql/connector/connection.py", line 319, in _open_connection
    self._socket.open_connection()
  File "/usr/lib/python2.6/site-packages/mysql/connector/network.py", line 393, in open_connection
    errno=2003, values=(self.server_host, msg))
InterfaceError: 2003: Can't connect to MySQL server on 'localhost' (111)
[2013-08-15 06:01:01,515]CRITICAL: The process is terminated with an exception.
Traceback (most recent call last):
  File "/home/cdnlab-gnp/gnp-deploy/obtain_ipaddr.py", line 170, in <module>
    autocommit=True)
  File "/usr/lib/python2.6/site-packages/mysql/connector/__init__.py", line 44, in Connect
    return MySQLConnection(*args, **kwargs)
  File "/usr/lib/python2.6/site-packages/mysql/connector/connection.py", line 108, in __init__
    self.connect(**kwargs)
  File "/usr/lib/python2.6/site-packages/mysql/connector/connection.py", line 356, in connect
    self._open_connection()
  File "/usr/lib/python2.6/site-packages/mysql/connector/connection.py", line 319, in _open_connection
    self._socket.open_connection()
  File "/usr/lib/python2.6/site-packages/mysql/connector/network.py", line 393, in open_connection
    errno=2003, values=(self.server_host, msg))
InterfaceError: 2003: Can't connect to MySQL server on 'localhost' (111)
[2013-08-15 07:01:01,625]CRITICAL: The process is terminated with an exception.
Traceback (most recent call last):
  File "/home/cdnlab-gnp/gnp-deploy/obtain_ipaddr.py", line 170, in <module>
    autocommit=True)
  File "/usr/lib/python2.6/site-packages/mysql/connector/__init__.py", line 44, in Connect
    return MySQLConnection(*args, **kwargs)
  File "/usr/lib/python2.6/site-packages/mysql/connector/connection.py", line 108, in __init__
    self.connect(**kwargs)
  File "/usr/lib/python2.6/site-packages/mysql/connector/connection.py", line 356, in connect
    self._open_connection()
  File "/usr/lib/python2.6/site-packages/mysql/connector/connection.py", line 319, in _open_connection
    self._socket.open_connection()
  File "/usr/lib/python2.6/site-packages/mysql/connector/network.py", line 393, in open_connection
    errno=2003, values=(self.server_host, msg))
InterfaceError: 2003: Can't connect to MySQL server on 'localhost' (111)
[2013-08-15 08:01:01,815]CRITICAL: The process is terminated with an exception.
Traceback (most recent call last):
  File "/home/cdnlab-gnp/gnp-deploy/obtain_ipaddr.py", line 170, in <module>
    autocommit=True)
  File "/usr/lib/python2.6/site-packages/mysql/connector/__init__.py", line 44, in Connect
    return MySQLConnection(*args, **kwargs)
  File "/usr/lib/python2.6/site-packages/mysql/connector/connection.py", line 108, in __init__
    self.connect(**kwargs)
  File "/usr/lib/python2.6/site-packages/mysql/connector/connection.py", line 356, in connect
    self._open_connection()
  File "/usr/lib/python2.6/site-packages/mysql/connector/connection.py", line 319, in _open_connection
    self._socket.open_connection()
  File "/usr/lib/python2.6/site-packages/mysql/connector/network.py", line 393, in open_connection
    errno=2003, values=(self.server_host, msg))
InterfaceError: 2003: Can't connect to MySQL server on 'localhost' (111)
[2013-08-15 09:01:01,777]CRITICAL: The process is terminated with an exception.
Traceback (most recent call last):
  File "/home/cdnlab-gnp/gnp-deploy/obtain_ipaddr.py", line 170, in <module>
    autocommit=True)
  File "/usr/lib/python2.6/site-packages/mysql/connector/__init__.py", line 44, in Connect
    return MySQLConnection(*args, **kwargs)
  File "/usr/lib/python2.6/site-packages/mysql/connector/connection.py", line 108, in __init__
    self.connect(**kwargs)
  File "/usr/lib/python2.6/site-packages/mysql/connector/connection.py", line 356, in connect
    self._open_connection()
  File "/usr/lib/python2.6/site-packages/mysql/connector/connection.py", line 319, in _open_connection
    self._socket.open_connection()
  File "/usr/lib/python2.6/site-packages/mysql/connector/network.py", line 393, in open_connection
    errno=2003, values=(self.server_host, msg))
InterfaceError: 2003: Can't connect to MySQL server on 'localhost' (111)
[2013-08-15 10:01:01,667]CRITICAL: The process is terminated with an exception.
Traceback (most recent call last):
  File "/home/cdnlab-gnp/gnp-deploy/obtain_ipaddr.py", line 170, in <module>
    autocommit=True)
  File "/usr/lib/python2.6/site-packages/mysql/connector/__init__.py", line 44, in Connect
    return MySQLConnection(*args, **kwargs)
  File "/usr/lib/python2.6/site-packages/mysql/connector/connection.py", line 108, in __init__
    self.connect(**kwargs)
  File "/usr/lib/python2.6/site-packages/mysql/connector/connection.py", line 356, in connect
    self._open_connection()
  File "/usr/lib/python2.6/site-packages/mysql/connector/connection.py", line 319, in _open_connection
    self._socket.open_connection()
  File "/usr/lib/python2.6/site-packages/mysql/connector/network.py", line 393, in open_connection
    errno=2003, values=(self.server_host, msg))
InterfaceError: 2003: Can't connect to MySQL server on 'localhost' (111)
[2013-08-15 11:01:01,870]CRITICAL: The process is terminated with an exception.
Traceback (most recent call last):
  File "/home/cdnlab-gnp/gnp-deploy/obtain_ipaddr.py", line 170, in <module>
    autocommit=True)
  File "/usr/lib/python2.6/site-packages/mysql/connector/__init__.py", line 44, in Connect
    return MySQLConnection(*args, **kwargs)
  File "/usr/lib/python2.6/site-packages/mysql/connector/connection.py", line 108, in __init__
    self.connect(**kwargs)
  File "/usr/lib/python2.6/site-packages/mysql/connector/connection.py", line 356, in connect
    self._open_connection()
  File "/usr/lib/python2.6/site-packages/mysql/connector/connection.py", line 319, in _open_connection
    self._socket.open_connection()
  File "/usr/lib/python2.6/site-packages/mysql/connector/network.py", line 393, in open_connection
    errno=2003, values=(self.server_host, msg))
InterfaceError: 2003: Can't connect to MySQL server on 'localhost' (111)
[2013-08-15 12:01:01,948]CRITICAL: The process is terminated with an exception.
Traceback (most recent call last):
  File "/home/cdnlab-gnp/gnp-deploy/obtain_ipaddr.py", line 170, in <module>
    autocommit=True)
  File "/usr/lib/python2.6/site-packages/mysql/connector/__init__.py", line 44, in Connect
    return MySQLConnection(*args, **kwargs)
  File "/usr/lib/python2.6/site-packages/mysql/connector/connection.py", line 108, in __init__
    self.connect(**kwargs)
  File "/usr/lib/python2.6/site-packages/mysql/connector/connection.py", line 356, in connect
    self._open_connection()
  File "/usr/lib/python2.6/site-packages/mysql/connector/connection.py", line 319, in _open_connection
    self._socket.open_connection()
  File "/usr/lib/python2.6/site-packages/mysql/connector/network.py", line 393, in open_connection
    errno=2003, values=(self.server_host, msg))
InterfaceError: 2003: Can't connect to MySQL server on 'localhost' (111)
[2013-08-15 13:01:01,147]CRITICAL: The process is terminated with an exception.
Traceback (most recent call last):
  File "/home/cdnlab-gnp/gnp-deploy/obtain_ipaddr.py", line 170, in <module>
    autocommit=True)
  File "/usr/lib/python2.6/site-packages/mysql/connector/__init__.py", line 44, in Connect
    return MySQLConnection(*args, **kwargs)
  File "/usr/lib/python2.6/site-packages/mysql/connector/connection.py", line 108, in __init__
    self.connect(**kwargs)
  File "/usr/lib/python2.6/site-packages/mysql/connector/connection.py", line 356, in connect
    self._open_connection()
  File "/usr/lib/python2.6/site-packages/mysql/connector/connection.py", line 319, in _open_connection
    self._socket.open_connection()
  File "/usr/lib/python2.6/site-packages/mysql/connector/network.py", line 393, in open_connection
    errno=2003, values=(self.server_host, msg))
InterfaceError: 2003: Can't connect to MySQL server on 'localhost' (111)
