[2013-07-31 12:32:15,071] The process is done normally.
[2013-07-31 14:04:20,603] The process is done normally.
[2013-07-31 16:04:21,318] The process is done normally.
[2013-07-31 18:04:20,515] The process is done normally.
[2013-07-31 20:04:20,818] The process is done normally.
[2013-07-31 22:04:30,653] The process is done normally.
[2013-08-01 00:01:04,468] The process is done normally.
[2013-08-01 02:01:04,544] The process is done normally.
[2013-08-01 04:01:04,338] The process is done normally.
[2013-08-01 06:01:04,567] The process is done normally.
[2013-08-01 08:01:04,437] The process is done normally.
[2013-08-01 10:01:04,180] The process is done normally.
[2013-08-13 14:01:02,762]CRITICAL: The process is terminated with an exception.
Traceback (most recent call last):
  File "/home/cdnlab-gnp/gnp-deploy/obtain_ipaddr.py", line 170, in <module>
    autocommit=True)
  File "/usr/lib/python2.6/site-packages/mysql/connector/__init__.py", line 44, in Connect
    return MySQLConnection(*args, **kwargs)
  File "/usr/lib/python2.6/site-packages/mysql/connector/connection.py", line 108, in __init__
    self.connect(**kwargs)
  File "/usr/lib/python2.6/site-packages/mysql/connector/connection.py", line 356, in connect
    self._open_connection()
  File "/usr/lib/python2.6/site-packages/mysql/connector/connection.py", line 319, in _open_connection
    self._socket.open_connection()
  File "/usr/lib/python2.6/site-packages/mysql/connector/network.py", line 393, in open_connection
    errno=2003, values=(self.server_host, msg))
InterfaceError: 2003: Can't connect to MySQL server on 'localhost' (111)
[2013-08-13 15:01:01,980]CRITICAL: The process is terminated with an exception.
Traceback (most recent call last):
  File "/home/cdnlab-gnp/gnp-deploy/obtain_ipaddr.py", line 170, in <module>
    autocommit=True)
  File "/usr/lib/python2.6/site-packages/mysql/connector/__init__.py", line 44, in Connect
    return MySQLConnection(*args, **kwargs)
  File "/usr/lib/python2.6/site-packages/mysql/connector/connection.py", line 108, in __init__
    self.connect(**kwargs)
  File "/usr/lib/python2.6/site-packages/mysql/connector/connection.py", line 356, in connect
    self._open_connection()
  File "/usr/lib/python2.6/site-packages/mysql/connector/connection.py", line 319, in _open_connection
    self._socket.open_connection()
  File "/usr/lib/python2.6/site-packages/mysql/connector/network.py", line 393, in open_connection
    errno=2003, values=(self.server_host, msg))
InterfaceError: 2003: Can't connect to MySQL server on 'localhost' (111)
[2013-08-13 16:01:02,027]CRITICAL: The process is terminated with an exception.
Traceback (most recent call last):
  File "/home/cdnlab-gnp/gnp-deploy/obtain_ipaddr.py", line 170, in <module>
    autocommit=True)
  File "/usr/lib/python2.6/site-packages/mysql/connector/__init__.py", line 44, in Connect
    return MySQLConnection(*args, **kwargs)
  File "/usr/lib/python2.6/site-packages/mysql/connector/connection.py", line 108, in __init__
    self.connect(**kwargs)
  File "/usr/lib/python2.6/site-packages/mysql/connector/connection.py", line 356, in connect
    self._open_connection()
  File "/usr/lib/python2.6/site-packages/mysql/connector/connection.py", line 319, in _open_connection
    self._socket.open_connection()
  File "/usr/lib/python2.6/site-packages/mysql/connector/network.py", line 393, in open_connection
    errno=2003, values=(self.server_host, msg))
InterfaceError: 2003: Can't connect to MySQL server on 'localhost' (111)
[2013-08-13 17:01:01,190]CRITICAL: The process is terminated with an exception.
Traceback (most recent call last):
  File "/home/cdnlab-gnp/gnp-deploy/obtain_ipaddr.py", line 170, in <module>
    autocommit=True)
  File "/usr/lib/python2.6/site-packages/mysql/connector/__init__.py", line 44, in Connect
    return MySQLConnection(*args, **kwargs)
  File "/usr/lib/python2.6/site-packages/mysql/connector/connection.py", line 108, in __init__
    self.connect(**kwargs)
  File "/usr/lib/python2.6/site-packages/mysql/connector/connection.py", line 356, in connect
    self._open_connection()
  File "/usr/lib/python2.6/site-packages/mysql/connector/connection.py", line 319, in _open_connection
    self._socket.open_connection()
  File "/usr/lib/python2.6/site-packages/mysql/connector/network.py", line 393, in open_connection
    errno=2003, values=(self.server_host, msg))
InterfaceError: 2003: Can't connect to MySQL server on 'localhost' (111)
[2013-08-13 18:01:02,077]CRITICAL: The process is terminated with an exception.
Traceback (most recent call last):
  File "/home/cdnlab-gnp/gnp-deploy/obtain_ipaddr.py", line 170, in <module>
    autocommit=True)
  File "/usr/lib/python2.6/site-packages/mysql/connector/__init__.py", line 44, in Connect
    return MySQLConnection(*args, **kwargs)
  File "/usr/lib/python2.6/site-packages/mysql/connector/connection.py", line 108, in __init__
    self.connect(**kwargs)
  File "/usr/lib/python2.6/site-packages/mysql/connector/connection.py", line 356, in connect
    self._open_connection()
  File "/usr/lib/python2.6/site-packages/mysql/connector/connection.py", line 319, in _open_connection
    self._socket.open_connection()
  File "/usr/lib/python2.6/site-packages/mysql/connector/network.py", line 393, in open_connection
    errno=2003, values=(self.server_host, msg))
InterfaceError: 2003: Can't connect to MySQL server on 'localhost' (111)
[2013-08-13 19:01:01,279]CRITICAL: The process is terminated with an exception.
Traceback (most recent call last):
  File "/home/cdnlab-gnp/gnp-deploy/obtain_ipaddr.py", line 170, in <module>
    autocommit=True)
  File "/usr/lib/python2.6/site-packages/mysql/connector/__init__.py", line 44, in Connect
    return MySQLConnection(*args, **kwargs)
  File "/usr/lib/python2.6/site-packages/mysql/connector/connection.py", line 108, in __init__
    self.connect(**kwargs)
  File "/usr/lib/python2.6/site-packages/mysql/connector/connection.py", line 356, in connect
    self._open_connection()
  File "/usr/lib/python2.6/site-packages/mysql/connector/connection.py", line 319, in _open_connection
    self._socket.open_connection()
  File "/usr/lib/python2.6/site-packages/mysql/connector/network.py", line 393, in open_connection
    errno=2003, values=(self.server_host, msg))
InterfaceError: 2003: Can't connect to MySQL server on 'localhost' (111)
[2013-08-13 20:01:01,564]CRITICAL: The process is terminated with an exception.
Traceback (most recent call last):
  File "/home/cdnlab-gnp/gnp-deploy/obtain_ipaddr.py", line 170, in <module>
    autocommit=True)
  File "/usr/lib/python2.6/site-packages/mysql/connector/__init__.py", line 44, in Connect
    return MySQLConnection(*args, **kwargs)
  File "/usr/lib/python2.6/site-packages/mysql/connector/connection.py", line 108, in __init__
    self.connect(**kwargs)
  File "/usr/lib/python2.6/site-packages/mysql/connector/connection.py", line 356, in connect
    self._open_connection()
  File "/usr/lib/python2.6/site-packages/mysql/connector/connection.py", line 319, in _open_connection
    self._socket.open_connection()
  File "/usr/lib/python2.6/site-packages/mysql/connector/network.py", line 393, in open_connection
    errno=2003, values=(self.server_host, msg))
InterfaceError: 2003: Can't connect to MySQL server on 'localhost' (111)
[2013-08-13 21:01:01,477]CRITICAL: The process is terminated with an exception.
Traceback (most recent call last):
  File "/home/cdnlab-gnp/gnp-deploy/obtain_ipaddr.py", line 170, in <module>
    autocommit=True)
  File "/usr/lib/python2.6/site-packages/mysql/connector/__init__.py", line 44, in Connect
    return MySQLConnection(*args, **kwargs)
  File "/usr/lib/python2.6/site-packages/mysql/connector/connection.py", line 108, in __init__
    self.connect(**kwargs)
  File "/usr/lib/python2.6/site-packages/mysql/connector/connection.py", line 356, in connect
    self._open_connection()
  File "/usr/lib/python2.6/site-packages/mysql/connector/connection.py", line 319, in _open_connection
    self._socket.open_connection()
  File "/usr/lib/python2.6/site-packages/mysql/connector/network.py", line 393, in open_connection
    errno=2003, values=(self.server_host, msg))
InterfaceError: 2003: Can't connect to MySQL server on 'localhost' (111)
[2013-08-13 22:01:02,055]CRITICAL: The process is terminated with an exception.
Traceback (most recent call last):
  File "/home/cdnlab-gnp/gnp-deploy/obtain_ipaddr.py", line 170, in <module>
    autocommit=True)
  File "/usr/lib/python2.6/site-packages/mysql/connector/__init__.py", line 44, in Connect
    return MySQLConnection(*args, **kwargs)
  File "/usr/lib/python2.6/site-packages/mysql/connector/connection.py", line 108, in __init__
    self.connect(**kwargs)
  File "/usr/lib/python2.6/site-packages/mysql/connector/connection.py", line 356, in connect
    self._open_connection()
  File "/usr/lib/python2.6/site-packages/mysql/connector/connection.py", line 319, in _open_connection
    self._socket.open_connection()
  File "/usr/lib/python2.6/site-packages/mysql/connector/network.py", line 393, in open_connection
    errno=2003, values=(self.server_host, msg))
InterfaceError: 2003: Can't connect to MySQL server on 'localhost' (111)
[2013-08-13 23:01:01,583]CRITICAL: The process is terminated with an exception.
Traceback (most recent call last):
  File "/home/cdnlab-gnp/gnp-deploy/obtain_ipaddr.py", line 170, in <module>
    autocommit=True)
  File "/usr/lib/python2.6/site-packages/mysql/connector/__init__.py", line 44, in Connect
    return MySQLConnection(*args, **kwargs)
  File "/usr/lib/python2.6/site-packages/mysql/connector/connection.py", line 108, in __init__
    self.connect(**kwargs)
  File "/usr/lib/python2.6/site-packages/mysql/connector/connection.py", line 356, in connect
    self._open_connection()
  File "/usr/lib/python2.6/site-packages/mysql/connector/connection.py", line 319, in _open_connection
    self._socket.open_connection()
  File "/usr/lib/python2.6/site-packages/mysql/connector/network.py", line 393, in open_connection
    errno=2003, values=(self.server_host, msg))
InterfaceError: 2003: Can't connect to MySQL server on 'localhost' (111)
[2013-08-14 00:01:01,436]CRITICAL: The process is terminated with an exception.
Traceback (most recent call last):
  File "/home/cdnlab-gnp/gnp-deploy/obtain_ipaddr.py", line 170, in <module>
    autocommit=True)
  File "/usr/lib/python2.6/site-packages/mysql/connector/__init__.py", line 44, in Connect
    return MySQLConnection(*args, **kwargs)
  File "/usr/lib/python2.6/site-packages/mysql/connector/connection.py", line 108, in __init__
    self.connect(**kwargs)
  File "/usr/lib/python2.6/site-packages/mysql/connector/connection.py", line 356, in connect
    self._open_connection()
  File "/usr/lib/python2.6/site-packages/mysql/connector/connection.py", line 319, in _open_connection
    self._socket.open_connection()
  File "/usr/lib/python2.6/site-packages/mysql/connector/network.py", line 393, in open_connection
    errno=2003, values=(self.server_host, msg))
InterfaceError: 2003: Can't connect to MySQL server on 'localhost' (111)
[2013-08-14 01:01:01,115]CRITICAL: The process is terminated with an exception.
Traceback (most recent call last):
  File "/home/cdnlab-gnp/gnp-deploy/obtain_ipaddr.py", line 170, in <module>
    autocommit=True)
  File "/usr/lib/python2.6/site-packages/mysql/connector/__init__.py", line 44, in Connect
    return MySQLConnection(*args, **kwargs)
  File "/usr/lib/python2.6/site-packages/mysql/connector/connection.py", line 108, in __init__
    self.connect(**kwargs)
  File "/usr/lib/python2.6/site-packages/mysql/connector/connection.py", line 356, in connect
    self._open_connection()
  File "/usr/lib/python2.6/site-packages/mysql/connector/connection.py", line 319, in _open_connection
    self._socket.open_connection()
  File "/usr/lib/python2.6/site-packages/mysql/connector/network.py", line 393, in open_connection
    errno=2003, values=(self.server_host, msg))
InterfaceError: 2003: Can't connect to MySQL server on 'localhost' (111)
[2013-08-14 02:01:01,147]CRITICAL: The process is terminated with an exception.
Traceback (most recent call last):
  File "/home/cdnlab-gnp/gnp-deploy/obtain_ipaddr.py", line 170, in <module>
    autocommit=True)
  File "/usr/lib/python2.6/site-packages/mysql/connector/__init__.py", line 44, in Connect
    return MySQLConnection(*args, **kwargs)
  File "/usr/lib/python2.6/site-packages/mysql/connector/connection.py", line 108, in __init__
    self.connect(**kwargs)
  File "/usr/lib/python2.6/site-packages/mysql/connector/connection.py", line 356, in connect
    self._open_connection()
  File "/usr/lib/python2.6/site-packages/mysql/connector/connection.py", line 319, in _open_connection
    self._socket.open_connection()
  File "/usr/lib/python2.6/site-packages/mysql/connector/network.py", line 393, in open_connection
    errno=2003, values=(self.server_host, msg))
InterfaceError: 2003: Can't connect to MySQL server on 'localhost' (111)
[2013-08-14 03:01:01,609]CRITICAL: The process is terminated with an exception.
Traceback (most recent call last):
  File "/home/cdnlab-gnp/gnp-deploy/obtain_ipaddr.py", line 170, in <module>
    autocommit=True)
  File "/usr/lib/python2.6/site-packages/mysql/connector/__init__.py", line 44, in Connect
    return MySQLConnection(*args, **kwargs)
  File "/usr/lib/python2.6/site-packages/mysql/connector/connection.py", line 108, in __init__
    self.connect(**kwargs)
  File "/usr/lib/python2.6/site-packages/mysql/connector/connection.py", line 356, in connect
    self._open_connection()
  File "/usr/lib/python2.6/site-packages/mysql/connector/connection.py", line 319, in _open_connection
    self._socket.open_connection()
  File "/usr/lib/python2.6/site-packages/mysql/connector/network.py", line 393, in open_connection
    errno=2003, values=(self.server_host, msg))
InterfaceError: 2003: Can't connect to MySQL server on 'localhost' (111)
[2013-08-14 04:01:01,666]CRITICAL: The process is terminated with an exception.
Traceback (most recent call last):
  File "/home/cdnlab-gnp/gnp-deploy/obtain_ipaddr.py", line 170, in <module>
    autocommit=True)
  File "/usr/lib/python2.6/site-packages/mysql/connector/__init__.py", line 44, in Connect
    return MySQLConnection(*args, **kwargs)
  File "/usr/lib/python2.6/site-packages/mysql/connector/connection.py", line 108, in __init__
    self.connect(**kwargs)
  File "/usr/lib/python2.6/site-packages/mysql/connector/connection.py", line 356, in connect
    self._open_connection()
  File "/usr/lib/python2.6/site-packages/mysql/connector/connection.py", line 319, in _open_connection
    self._socket.open_connection()
  File "/usr/lib/python2.6/site-packages/mysql/connector/network.py", line 393, in open_connection
    errno=2003, values=(self.server_host, msg))
InterfaceError: 2003: Can't connect to MySQL server on 'localhost' (111)
[2013-08-14 05:01:02,041]CRITICAL: The process is terminated with an exception.
Traceback (most recent call last):
  File "/home/cdnlab-gnp/gnp-deploy/obtain_ipaddr.py", line 170, in <module>
    autocommit=True)
  File "/usr/lib/python2.6/site-packages/mysql/connector/__init__.py", line 44, in Connect
    return MySQLConnection(*args, **kwargs)
  File "/usr/lib/python2.6/site-packages/mysql/connector/connection.py", line 108, in __init__
    self.connect(**kwargs)
  File "/usr/lib/python2.6/site-packages/mysql/connector/connection.py", line 356, in connect
    self._open_connection()
  File "/usr/lib/python2.6/site-packages/mysql/connector/connection.py", line 319, in _open_connection
    self._socket.open_connection()
  File "/usr/lib/python2.6/site-packages/mysql/connector/network.py", line 393, in open_connection
    errno=2003, values=(self.server_host, msg))
InterfaceError: 2003: Can't connect to MySQL server on 'localhost' (111)
[2013-08-14 06:01:01,227]CRITICAL: The process is terminated with an exception.
Traceback (most recent call last):
  File "/home/cdnlab-gnp/gnp-deploy/obtain_ipaddr.py", line 170, in <module>
    autocommit=True)
  File "/usr/lib/python2.6/site-packages/mysql/connector/__init__.py", line 44, in Connect
    return MySQLConnection(*args, **kwargs)
  File "/usr/lib/python2.6/site-packages/mysql/connector/connection.py", line 108, in __init__
    self.connect(**kwargs)
  File "/usr/lib/python2.6/site-packages/mysql/connector/connection.py", line 356, in connect
    self._open_connection()
  File "/usr/lib/python2.6/site-packages/mysql/connector/connection.py", line 319, in _open_connection
    self._socket.open_connection()
  File "/usr/lib/python2.6/site-packages/mysql/connector/network.py", line 393, in open_connection
    errno=2003, values=(self.server_host, msg))
InterfaceError: 2003: Can't connect to MySQL server on 'localhost' (111)
[2013-08-14 07:01:02,063]CRITICAL: The process is terminated with an exception.
Traceback (most recent call last):
  File "/home/cdnlab-gnp/gnp-deploy/obtain_ipaddr.py", line 170, in <module>
    autocommit=True)
  File "/usr/lib/python2.6/site-packages/mysql/connector/__init__.py", line 44, in Connect
    return MySQLConnection(*args, **kwargs)
  File "/usr/lib/python2.6/site-packages/mysql/connector/connection.py", line 108, in __init__
    self.connect(**kwargs)
  File "/usr/lib/python2.6/site-packages/mysql/connector/connection.py", line 356, in connect
    self._open_connection()
  File "/usr/lib/python2.6/site-packages/mysql/connector/connection.py", line 319, in _open_connection
    self._socket.open_connection()
  File "/usr/lib/python2.6/site-packages/mysql/connector/network.py", line 393, in open_connection
    errno=2003, values=(self.server_host, msg))
InterfaceError: 2003: Can't connect to MySQL server on 'localhost' (111)
[2013-08-14 08:01:01,538]CRITICAL: The process is terminated with an exception.
Traceback (most recent call last):
  File "/home/cdnlab-gnp/gnp-deploy/obtain_ipaddr.py", line 170, in <module>
    autocommit=True)
  File "/usr/lib/python2.6/site-packages/mysql/connector/__init__.py", line 44, in Connect
    return MySQLConnection(*args, **kwargs)
  File "/usr/lib/python2.6/site-packages/mysql/connector/connection.py", line 108, in __init__
    self.connect(**kwargs)
  File "/usr/lib/python2.6/site-packages/mysql/connector/connection.py", line 356, in connect
    self._open_connection()
  File "/usr/lib/python2.6/site-packages/mysql/connector/connection.py", line 319, in _open_connection
    self._socket.open_connection()
  File "/usr/lib/python2.6/site-packages/mysql/connector/network.py", line 393, in open_connection
    errno=2003, values=(self.server_host, msg))
InterfaceError: 2003: Can't connect to MySQL server on 'localhost' (111)
[2013-08-14 09:01:02,061]CRITICAL: The process is terminated with an exception.
Traceback (most recent call last):
  File "/home/cdnlab-gnp/gnp-deploy/obtain_ipaddr.py", line 170, in <module>
    autocommit=True)
  File "/usr/lib/python2.6/site-packages/mysql/connector/__init__.py", line 44, in Connect
    return MySQLConnection(*args, **kwargs)
  File "/usr/lib/python2.6/site-packages/mysql/connector/connection.py", line 108, in __init__
    self.connect(**kwargs)
  File "/usr/lib/python2.6/site-packages/mysql/connector/connection.py", line 356, in connect
    self._open_connection()
  File "/usr/lib/python2.6/site-packages/mysql/connector/connection.py", line 319, in _open_connection
    self._socket.open_connection()
  File "/usr/lib/python2.6/site-packages/mysql/connector/network.py", line 393, in open_connection
    errno=2003, values=(self.server_host, msg))
InterfaceError: 2003: Can't connect to MySQL server on 'localhost' (111)
[2013-08-14 10:01:01,849]CRITICAL: The process is terminated with an exception.
Traceback (most recent call last):
  File "/home/cdnlab-gnp/gnp-deploy/obtain_ipaddr.py", line 170, in <module>
    autocommit=True)
  File "/usr/lib/python2.6/site-packages/mysql/connector/__init__.py", line 44, in Connect
    return MySQLConnection(*args, **kwargs)
  File "/usr/lib/python2.6/site-packages/mysql/connector/connection.py", line 108, in __init__
    self.connect(**kwargs)
  File "/usr/lib/python2.6/site-packages/mysql/connector/connection.py", line 356, in connect
    self._open_connection()
  File "/usr/lib/python2.6/site-packages/mysql/connector/connection.py", line 319, in _open_connection
    self._socket.open_connection()
  File "/usr/lib/python2.6/site-packages/mysql/connector/network.py", line 393, in open_connection
    errno=2003, values=(self.server_host, msg))
InterfaceError: 2003: Can't connect to MySQL server on 'localhost' (111)
[2013-08-14 11:01:02,002]CRITICAL: The process is terminated with an exception.
Traceback (most recent call last):
  File "/home/cdnlab-gnp/gnp-deploy/obtain_ipaddr.py", line 170, in <module>
    autocommit=True)
  File "/usr/lib/python2.6/site-packages/mysql/connector/__init__.py", line 44, in Connect
    return MySQLConnection(*args, **kwargs)
  File "/usr/lib/python2.6/site-packages/mysql/connector/connection.py", line 108, in __init__
    self.connect(**kwargs)
  File "/usr/lib/python2.6/site-packages/mysql/connector/connection.py", line 356, in connect
    self._open_connection()
  File "/usr/lib/python2.6/site-packages/mysql/connector/connection.py", line 319, in _open_connection
    self._socket.open_connection()
  File "/usr/lib/python2.6/site-packages/mysql/connector/network.py", line 393, in open_connection
    errno=2003, values=(self.server_host, msg))
InterfaceError: 2003: Can't connect to MySQL server on 'localhost' (111)
[2013-08-14 12:01:01,527]CRITICAL: The process is terminated with an exception.
Traceback (most recent call last):
  File "/home/cdnlab-gnp/gnp-deploy/obtain_ipaddr.py", line 170, in <module>
    autocommit=True)
  File "/usr/lib/python2.6/site-packages/mysql/connector/__init__.py", line 44, in Connect
    return MySQLConnection(*args, **kwargs)
  File "/usr/lib/python2.6/site-packages/mysql/connector/connection.py", line 108, in __init__
    self.connect(**kwargs)
  File "/usr/lib/python2.6/site-packages/mysql/connector/connection.py", line 356, in connect
    self._open_connection()
  File "/usr/lib/python2.6/site-packages/mysql/connector/connection.py", line 319, in _open_connection
    self._socket.open_connection()
  File "/usr/lib/python2.6/site-packages/mysql/connector/network.py", line 393, in open_connection
    errno=2003, values=(self.server_host, msg))
InterfaceError: 2003: Can't connect to MySQL server on 'localhost' (111)
[2013-08-14 13:01:01,695]CRITICAL: The process is terminated with an exception.
Traceback (most recent call last):
  File "/home/cdnlab-gnp/gnp-deploy/obtain_ipaddr.py", line 170, in <module>
    autocommit=True)
  File "/usr/lib/python2.6/site-packages/mysql/connector/__init__.py", line 44, in Connect
    return MySQLConnection(*args, **kwargs)
  File "/usr/lib/python2.6/site-packages/mysql/connector/connection.py", line 108, in __init__
    self.connect(**kwargs)
  File "/usr/lib/python2.6/site-packages/mysql/connector/connection.py", line 356, in connect
    self._open_connection()
  File "/usr/lib/python2.6/site-packages/mysql/connector/connection.py", line 319, in _open_connection
    self._socket.open_connection()
  File "/usr/lib/python2.6/site-packages/mysql/connector/network.py", line 393, in open_connection
    errno=2003, values=(self.server_host, msg))
InterfaceError: 2003: Can't connect to MySQL server on 'localhost' (111)
[2013-08-14 14:01:01,672]CRITICAL: The process is terminated with an exception.
Traceback (most recent call last):
  File "/home/cdnlab-gnp/gnp-deploy/obtain_ipaddr.py", line 170, in <module>
    autocommit=True)
  File "/usr/lib/python2.6/site-packages/mysql/connector/__init__.py", line 44, in Connect
    return MySQLConnection(*args, **kwargs)
  File "/usr/lib/python2.6/site-packages/mysql/connector/connection.py", line 108, in __init__
    self.connect(**kwargs)
  File "/usr/lib/python2.6/site-packages/mysql/connector/connection.py", line 356, in connect
    self._open_connection()
  File "/usr/lib/python2.6/site-packages/mysql/connector/connection.py", line 319, in _open_connection
    self._socket.open_connection()
  File "/usr/lib/python2.6/site-packages/mysql/connector/network.py", line 393, in open_connection
    errno=2003, values=(self.server_host, msg))
InterfaceError: 2003: Can't connect to MySQL server on 'localhost' (111)
[2013-08-14 15:01:01,253]CRITICAL: The process is terminated with an exception.
Traceback (most recent call last):
  File "/home/cdnlab-gnp/gnp-deploy/obtain_ipaddr.py", line 170, in <module>
    autocommit=True)
  File "/usr/lib/python2.6/site-packages/mysql/connector/__init__.py", line 44, in Connect
    return MySQLConnection(*args, **kwargs)
  File "/usr/lib/python2.6/site-packages/mysql/connector/connection.py", line 108, in __init__
    self.connect(**kwargs)
  File "/usr/lib/python2.6/site-packages/mysql/connector/connection.py", line 356, in connect
    self._open_connection()
  File "/usr/lib/python2.6/site-packages/mysql/connector/connection.py", line 319, in _open_connection
    self._socket.open_connection()
  File "/usr/lib/python2.6/site-packages/mysql/connector/network.py", line 393, in open_connection
    errno=2003, values=(self.server_host, msg))
InterfaceError: 2003: Can't connect to MySQL server on 'localhost' (111)
[2020-01-24 09:01:02,518]CRITICAL: The process is terminated with an exception.
Traceback (most recent call last):
  File "/home/cdnlab-gnp/gnp-deploy/obtain_ipaddr.py", line 170, in <module>
    autocommit=True)
  File "/usr/lib/python2.6/site-packages/mysql/connector/__init__.py", line 44, in Connect
    return MySQLConnection(*args, **kwargs)
  File "/usr/lib/python2.6/site-packages/mysql/connector/connection.py", line 108, in __init__
    self.connect(**kwargs)
  File "/usr/lib/python2.6/site-packages/mysql/connector/connection.py", line 356, in connect
    self._open_connection()
  File "/usr/lib/python2.6/site-packages/mysql/connector/connection.py", line 319, in _open_connection
    self._socket.open_connection()
  File "/usr/lib/python2.6/site-packages/mysql/connector/network.py", line 393, in open_connection
    errno=2003, values=(self.server_host, msg))
InterfaceError: 2003: Can't connect to MySQL server on 'localhost' (111)
[2013-08-16 12:01:01,781]CRITICAL: The process is terminated with an exception.
Traceback (most recent call last):
  File "/home/cdnlab-gnp/gnp-deploy/obtain_ipaddr.py", line 170, in <module>
    autocommit=True)
  File "/usr/lib/python2.6/site-packages/mysql/connector/__init__.py", line 44, in Connect
    return MySQLConnection(*args, **kwargs)
  File "/usr/lib/python2.6/site-packages/mysql/connector/connection.py", line 108, in __init__
    self.connect(**kwargs)
  File "/usr/lib/python2.6/site-packages/mysql/connector/connection.py", line 356, in connect
    self._open_connection()
  File "/usr/lib/python2.6/site-packages/mysql/connector/connection.py", line 319, in _open_connection
    self._socket.open_connection()
  File "/usr/lib/python2.6/site-packages/mysql/connector/network.py", line 393, in open_connection
    errno=2003, values=(self.server_host, msg))
InterfaceError: 2003: Can't connect to MySQL server on 'localhost' (111)
[2013-08-16 13:01:01,535]CRITICAL: The process is terminated with an exception.
Traceback (most recent call last):
  File "/home/cdnlab-gnp/gnp-deploy/obtain_ipaddr.py", line 170, in <module>
    autocommit=True)
  File "/usr/lib/python2.6/site-packages/mysql/connector/__init__.py", line 44, in Connect
    return MySQLConnection(*args, **kwargs)
  File "/usr/lib/python2.6/site-packages/mysql/connector/connection.py", line 108, in __init__
    self.connect(**kwargs)
  File "/usr/lib/python2.6/site-packages/mysql/connector/connection.py", line 356, in connect
    self._open_connection()
  File "/usr/lib/python2.6/site-packages/mysql/connector/connection.py", line 319, in _open_connection
    self._socket.open_connection()
  File "/usr/lib/python2.6/site-packages/mysql/connector/network.py", line 393, in open_connection
    errno=2003, values=(self.server_host, msg))
InterfaceError: 2003: Can't connect to MySQL server on 'localhost' (111)
[2013-08-16 14:01:23,241]CRITICAL: The process is terminated with an exception.
Traceback (most recent call last):
  File "/home/cdnlab-gnp/gnp-deploy/obtain_ipaddr.py", line 170, in <module>
    autocommit=True)
  File "/usr/lib/python2.6/site-packages/mysql/connector/__init__.py", line 44, in Connect
    return MySQLConnection(*args, **kwargs)
  File "/usr/lib/python2.6/site-packages/mysql/connector/connection.py", line 108, in __init__
    self.connect(**kwargs)
  File "/usr/lib/python2.6/site-packages/mysql/connector/connection.py", line 356, in connect
    self._open_connection()
  File "/usr/lib/python2.6/site-packages/mysql/connector/connection.py", line 319, in _open_connection
    self._socket.open_connection()
  File "/usr/lib/python2.6/site-packages/mysql/connector/network.py", line 393, in open_connection
    errno=2003, values=(self.server_host, msg))
InterfaceError: 2003: Can't connect to MySQL server on 'localhost' (111)
[2013-08-16 15:01:11,283]CRITICAL: The process is terminated with an exception.
Traceback (most recent call last):
  File "/home/cdnlab-gnp/gnp-deploy/obtain_ipaddr.py", line 170, in <module>
    autocommit=True)
  File "/usr/lib/python2.6/site-packages/mysql/connector/__init__.py", line 44, in Connect
    return MySQLConnection(*args, **kwargs)
  File "/usr/lib/python2.6/site-packages/mysql/connector/connection.py", line 108, in __init__
    self.connect(**kwargs)
  File "/usr/lib/python2.6/site-packages/mysql/connector/connection.py", line 356, in connect
    self._open_connection()
  File "/usr/lib/python2.6/site-packages/mysql/connector/connection.py", line 319, in _open_connection
    self._socket.open_connection()
  File "/usr/lib/python2.6/site-packages/mysql/connector/network.py", line 393, in open_connection
    errno=2003, values=(self.server_host, msg))
InterfaceError: 2003: Can't connect to MySQL server on 'localhost' (111)
[2013-08-16 16:01:02,568]CRITICAL: The process is terminated with an exception.
Traceback (most recent call last):
  File "/home/cdnlab-gnp/gnp-deploy/obtain_ipaddr.py", line 170, in <module>
    autocommit=True)
  File "/usr/lib/python2.6/site-packages/mysql/connector/__init__.py", line 44, in Connect
    return MySQLConnection(*args, **kwargs)
  File "/usr/lib/python2.6/site-packages/mysql/connector/connection.py", line 108, in __init__
    self.connect(**kwargs)
  File "/usr/lib/python2.6/site-packages/mysql/connector/connection.py", line 356, in connect
    self._open_connection()
  File "/usr/lib/python2.6/site-packages/mysql/connector/connection.py", line 319, in _open_connection
    self._socket.open_connection()
  File "/usr/lib/python2.6/site-packages/mysql/connector/network.py", line 393, in open_connection
    errno=2003, values=(self.server_host, msg))
InterfaceError: 2003: Can't connect to MySQL server on 'localhost' (111)
