[2013-07-31 12:30:04,375] The process is done normally.
[2013-07-31 14:04:22,457] The process is done normally.
[2013-07-31 16:04:21,036] The process is done normally.
[2013-07-31 18:04:22,129] The process is done normally.
[2013-07-31 20:04:21,989] The process is done normally.
[2013-07-31 22:04:23,502] The process is done normally.
[2013-08-01 00:01:04,358] The process is done normally.
[2013-08-01 02:01:04,524] The process is done normally.
[2013-08-01 04:01:04,543] The process is done normally.
[2013-08-01 06:01:04,551] The process is done normally.
[2013-08-01 08:01:05,110] The process is done normally.
[2013-08-01 10:01:04,938] The process is done normally.
[2013-10-07 17:01:02,835]CRITICAL: The process is terminated with an exception.
Traceback (most recent call last):
  File "/home/cdnlab-gnp/gnp-deploy/obtain_ipaddr.py", line 170, in <module>
    autocommit=True)
  File "/usr/lib/python2.6/site-packages/mysql/connector/__init__.py", line 44, in Connect
    return MySQLConnection(*args, **kwargs)
  File "/usr/lib/python2.6/site-packages/mysql/connector/connection.py", line 108, in __init__
    self.connect(**kwargs)
  File "/usr/lib/python2.6/site-packages/mysql/connector/connection.py", line 356, in connect
    self._open_connection()
  File "/usr/lib/python2.6/site-packages/mysql/connector/connection.py", line 319, in _open_connection
    self._socket.open_connection()
  File "/usr/lib/python2.6/site-packages/mysql/connector/network.py", line 393, in open_connection
    errno=2003, values=(self.server_host, msg))
InterfaceError: 2003: Can't connect to MySQL server on 'localhost' (111)
[2013-10-07 18:01:01,977]CRITICAL: The process is terminated with an exception.
Traceback (most recent call last):
  File "/home/cdnlab-gnp/gnp-deploy/obtain_ipaddr.py", line 170, in <module>
    autocommit=True)
  File "/usr/lib/python2.6/site-packages/mysql/connector/__init__.py", line 44, in Connect
    return MySQLConnection(*args, **kwargs)
  File "/usr/lib/python2.6/site-packages/mysql/connector/connection.py", line 108, in __init__
    self.connect(**kwargs)
  File "/usr/lib/python2.6/site-packages/mysql/connector/connection.py", line 356, in connect
    self._open_connection()
  File "/usr/lib/python2.6/site-packages/mysql/connector/connection.py", line 319, in _open_connection
    self._socket.open_connection()
  File "/usr/lib/python2.6/site-packages/mysql/connector/network.py", line 393, in open_connection
    errno=2003, values=(self.server_host, msg))
InterfaceError: 2003: Can't connect to MySQL server on 'localhost' (111)
[2013-10-07 19:01:01,183]CRITICAL: The process is terminated with an exception.
Traceback (most recent call last):
  File "/home/cdnlab-gnp/gnp-deploy/obtain_ipaddr.py", line 170, in <module>
    autocommit=True)
  File "/usr/lib/python2.6/site-packages/mysql/connector/__init__.py", line 44, in Connect
    return MySQLConnection(*args, **kwargs)
  File "/usr/lib/python2.6/site-packages/mysql/connector/connection.py", line 108, in __init__
    self.connect(**kwargs)
  File "/usr/lib/python2.6/site-packages/mysql/connector/connection.py", line 356, in connect
    self._open_connection()
  File "/usr/lib/python2.6/site-packages/mysql/connector/connection.py", line 319, in _open_connection
    self._socket.open_connection()
  File "/usr/lib/python2.6/site-packages/mysql/connector/network.py", line 393, in open_connection
    errno=2003, values=(self.server_host, msg))
InterfaceError: 2003: Can't connect to MySQL server on 'localhost' (111)
