[2013-07-31 12:32:24,357] The process is done normally.
[2013-07-31 14:04:22,288] The process is done normally.
[2013-07-31 16:04:21,793] The process is done normally.
[2013-07-31 18:04:21,872] The process is done normally.
[2013-07-31 20:04:22,619] The process is done normally.
[2013-07-31 22:04:31,576] The process is done normally.
[2013-08-01 00:01:04,399] The process is done normally.
[2013-08-01 02:01:04,460] The process is done normally.
[2013-08-01 04:01:04,509] The process is done normally.
[2013-08-01 06:01:04,861] The process is done normally.
[2013-08-01 08:01:04,248] The process is done normally.
[2013-08-01 10:01:04,545] The process is done normally.
[2013-08-22 12:16:24,509]CRITICAL: The process is terminated with an exception.
Traceback (most recent call last):
  File "/home/cdnlab-gnp/gnp-deploy/obtain_ipaddr.py", line 130, in scanner
    saveResult()
  File "/home/cdnlab-gnp/gnp-deploy/obtain_ipaddr.py", line 156, in saveResult
    updater.execute(update, row)
  File "/usr/lib/python2.6/site-packages/mysql/connector/cursor.py", line 392, in execute
    self._handle_result(self._connection.cmd_query(stmt))
  File "/usr/lib/python2.6/site-packages/mysql/connector/connection.py", line 584, in cmd_query
    statement))
  File "/usr/lib/python2.6/site-packages/mysql/connector/connection.py", line 506, in _handle_result
    raise errors.get_exception(packet)
ProgrammingError: 1146 (42S02): Table 'cdnlab.roundtrip' doesn't exist
[2013-08-22 13:15:28,743]CRITICAL: The process is terminated with an exception.
Traceback (most recent call last):
  File "/home/cdnlab-gnp/gnp-deploy/obtain_ipaddr.py", line 130, in scanner
    saveResult()
  File "/home/cdnlab-gnp/gnp-deploy/obtain_ipaddr.py", line 156, in saveResult
    updater.execute(update, row)
  File "/usr/lib/python2.6/site-packages/mysql/connector/cursor.py", line 392, in execute
    self._handle_result(self._connection.cmd_query(stmt))
  File "/usr/lib/python2.6/site-packages/mysql/connector/connection.py", line 584, in cmd_query
    statement))
  File "/usr/lib/python2.6/site-packages/mysql/connector/connection.py", line 506, in _handle_result
    raise errors.get_exception(packet)
ProgrammingError: 1146 (42S02): Table 'cdnlab.roundtrip' doesn't exist
[2013-08-22 14:16:27,792]CRITICAL: The process is terminated with an exception.
Traceback (most recent call last):
  File "/home/cdnlab-gnp/gnp-deploy/obtain_ipaddr.py", line 130, in scanner
    saveResult()
  File "/home/cdnlab-gnp/gnp-deploy/obtain_ipaddr.py", line 156, in saveResult
    updater.execute(update, row)
  File "/usr/lib/python2.6/site-packages/mysql/connector/cursor.py", line 392, in execute
    self._handle_result(self._connection.cmd_query(stmt))
  File "/usr/lib/python2.6/site-packages/mysql/connector/connection.py", line 584, in cmd_query
    statement))
  File "/usr/lib/python2.6/site-packages/mysql/connector/connection.py", line 506, in _handle_result
    raise errors.get_exception(packet)
ProgrammingError: 1146 (42S02): Table 'cdnlab.roundtrip' doesn't exist
