[2013-07-31 12:28:48,260] The process is done normally.
[2013-07-31 14:04:22,646] The process is done normally.
[2013-07-31 16:04:30,803] The process is done normally.
[2013-07-31 18:04:22,083] The process is done normally.
[2013-07-31 20:04:21,896] The process is done normally.
[2013-07-31 22:04:21,219] The process is done normally.
[2013-08-01 00:01:05,046] The process is done normally.
[2013-08-01 02:01:04,909] The process is done normally.
[2013-08-01 04:01:04,216] The process is done normally.
[2013-08-01 06:01:05,083] The process is done normally.
[2013-08-01 08:01:05,004] The process is done normally.
[2013-08-01 10:01:04,488] The process is done normally.
[2013-08-15 18:01:02,053]CRITICAL: The process is terminated with an exception.
Traceback (most recent call last):
  File "/home/cdnlab-gnp/gnp-deploy/obtain_ipaddr.py", line 170, in <module>
    autocommit=True)
  File "/usr/lib/python2.6/site-packages/mysql/connector/__init__.py", line 44, in Connect
    return MySQLConnection(*args, **kwargs)
  File "/usr/lib/python2.6/site-packages/mysql/connector/connection.py", line 108, in __init__
    self.connect(**kwargs)
  File "/usr/lib/python2.6/site-packages/mysql/connector/connection.py", line 356, in connect
    self._open_connection()
  File "/usr/lib/python2.6/site-packages/mysql/connector/connection.py", line 319, in _open_connection
    self._socket.open_connection()
  File "/usr/lib/python2.6/site-packages/mysql/connector/network.py", line 393, in open_connection
    errno=2003, values=(self.server_host, msg))
InterfaceError: 2003: Can't connect to MySQL server on 'localhost' (111)
[2013-08-15 19:01:01,822]CRITICAL: The process is terminated with an exception.
Traceback (most recent call last):
  File "/home/cdnlab-gnp/gnp-deploy/obtain_ipaddr.py", line 170, in <module>
    autocommit=True)
  File "/usr/lib/python2.6/site-packages/mysql/connector/__init__.py", line 44, in Connect
    return MySQLConnection(*args, **kwargs)
  File "/usr/lib/python2.6/site-packages/mysql/connector/connection.py", line 108, in __init__
    self.connect(**kwargs)
  File "/usr/lib/python2.6/site-packages/mysql/connector/connection.py", line 356, in connect
    self._open_connection()
  File "/usr/lib/python2.6/site-packages/mysql/connector/connection.py", line 319, in _open_connection
    self._socket.open_connection()
  File "/usr/lib/python2.6/site-packages/mysql/connector/network.py", line 393, in open_connection
    errno=2003, values=(self.server_host, msg))
InterfaceError: 2003: Can't connect to MySQL server on 'localhost' (111)
[2013-08-15 20:01:01,459]CRITICAL: The process is terminated with an exception.
Traceback (most recent call last):
  File "/home/cdnlab-gnp/gnp-deploy/obtain_ipaddr.py", line 170, in <module>
    autocommit=True)
  File "/usr/lib/python2.6/site-packages/mysql/connector/__init__.py", line 44, in Connect
    return MySQLConnection(*args, **kwargs)
  File "/usr/lib/python2.6/site-packages/mysql/connector/connection.py", line 108, in __init__
    self.connect(**kwargs)
  File "/usr/lib/python2.6/site-packages/mysql/connector/connection.py", line 356, in connect
    self._open_connection()
  File "/usr/lib/python2.6/site-packages/mysql/connector/connection.py", line 319, in _open_connection
    self._socket.open_connection()
  File "/usr/lib/python2.6/site-packages/mysql/connector/network.py", line 393, in open_connection
    errno=2003, values=(self.server_host, msg))
InterfaceError: 2003: Can't connect to MySQL server on 'localhost' (111)
[2013-08-15 21:01:01,223]CRITICAL: The process is terminated with an exception.
Traceback (most recent call last):
  File "/home/cdnlab-gnp/gnp-deploy/obtain_ipaddr.py", line 170, in <module>
    autocommit=True)
  File "/usr/lib/python2.6/site-packages/mysql/connector/__init__.py", line 44, in Connect
    return MySQLConnection(*args, **kwargs)
  File "/usr/lib/python2.6/site-packages/mysql/connector/connection.py", line 108, in __init__
    self.connect(**kwargs)
  File "/usr/lib/python2.6/site-packages/mysql/connector/connection.py", line 356, in connect
    self._open_connection()
  File "/usr/lib/python2.6/site-packages/mysql/connector/connection.py", line 319, in _open_connection
    self._socket.open_connection()
  File "/usr/lib/python2.6/site-packages/mysql/connector/network.py", line 393, in open_connection
    errno=2003, values=(self.server_host, msg))
InterfaceError: 2003: Can't connect to MySQL server on 'localhost' (111)
[2013-08-15 22:01:01,669]CRITICAL: The process is terminated with an exception.
Traceback (most recent call last):
  File "/home/cdnlab-gnp/gnp-deploy/obtain_ipaddr.py", line 170, in <module>
    autocommit=True)
  File "/usr/lib/python2.6/site-packages/mysql/connector/__init__.py", line 44, in Connect
    return MySQLConnection(*args, **kwargs)
  File "/usr/lib/python2.6/site-packages/mysql/connector/connection.py", line 108, in __init__
    self.connect(**kwargs)
  File "/usr/lib/python2.6/site-packages/mysql/connector/connection.py", line 356, in connect
    self._open_connection()
  File "/usr/lib/python2.6/site-packages/mysql/connector/connection.py", line 319, in _open_connection
    self._socket.open_connection()
  File "/usr/lib/python2.6/site-packages/mysql/connector/network.py", line 393, in open_connection
    errno=2003, values=(self.server_host, msg))
InterfaceError: 2003: Can't connect to MySQL server on 'localhost' (111)
[2013-08-15 23:01:01,103]CRITICAL: The process is terminated with an exception.
Traceback (most recent call last):
  File "/home/cdnlab-gnp/gnp-deploy/obtain_ipaddr.py", line 170, in <module>
    autocommit=True)
  File "/usr/lib/python2.6/site-packages/mysql/connector/__init__.py", line 44, in Connect
    return MySQLConnection(*args, **kwargs)
  File "/usr/lib/python2.6/site-packages/mysql/connector/connection.py", line 108, in __init__
    self.connect(**kwargs)
  File "/usr/lib/python2.6/site-packages/mysql/connector/connection.py", line 356, in connect
    self._open_connection()
  File "/usr/lib/python2.6/site-packages/mysql/connector/connection.py", line 319, in _open_connection
    self._socket.open_connection()
  File "/usr/lib/python2.6/site-packages/mysql/connector/network.py", line 393, in open_connection
    errno=2003, values=(self.server_host, msg))
InterfaceError: 2003: Can't connect to MySQL server on 'localhost' (111)
[2013-08-16 00:01:01,609]CRITICAL: The process is terminated with an exception.
Traceback (most recent call last):
  File "/home/cdnlab-gnp/gnp-deploy/obtain_ipaddr.py", line 170, in <module>
    autocommit=True)
  File "/usr/lib/python2.6/site-packages/mysql/connector/__init__.py", line 44, in Connect
    return MySQLConnection(*args, **kwargs)
  File "/usr/lib/python2.6/site-packages/mysql/connector/connection.py", line 108, in __init__
    self.connect(**kwargs)
  File "/usr/lib/python2.6/site-packages/mysql/connector/connection.py", line 356, in connect
    self._open_connection()
  File "/usr/lib/python2.6/site-packages/mysql/connector/connection.py", line 319, in _open_connection
    self._socket.open_connection()
  File "/usr/lib/python2.6/site-packages/mysql/connector/network.py", line 393, in open_connection
    errno=2003, values=(self.server_host, msg))
InterfaceError: 2003: Can't connect to MySQL server on 'localhost' (111)
[2013-08-16 01:01:01,420]CRITICAL: The process is terminated with an exception.
Traceback (most recent call last):
  File "/home/cdnlab-gnp/gnp-deploy/obtain_ipaddr.py", line 170, in <module>
    autocommit=True)
  File "/usr/lib/python2.6/site-packages/mysql/connector/__init__.py", line 44, in Connect
    return MySQLConnection(*args, **kwargs)
  File "/usr/lib/python2.6/site-packages/mysql/connector/connection.py", line 108, in __init__
    self.connect(**kwargs)
  File "/usr/lib/python2.6/site-packages/mysql/connector/connection.py", line 356, in connect
    self._open_connection()
  File "/usr/lib/python2.6/site-packages/mysql/connector/connection.py", line 319, in _open_connection
    self._socket.open_connection()
  File "/usr/lib/python2.6/site-packages/mysql/connector/network.py", line 393, in open_connection
    errno=2003, values=(self.server_host, msg))
InterfaceError: 2003: Can't connect to MySQL server on 'localhost' (111)
[2013-08-16 02:01:01,450]CRITICAL: The process is terminated with an exception.
Traceback (most recent call last):
  File "/home/cdnlab-gnp/gnp-deploy/obtain_ipaddr.py", line 170, in <module>
    autocommit=True)
  File "/usr/lib/python2.6/site-packages/mysql/connector/__init__.py", line 44, in Connect
    return MySQLConnection(*args, **kwargs)
  File "/usr/lib/python2.6/site-packages/mysql/connector/connection.py", line 108, in __init__
    self.connect(**kwargs)
  File "/usr/lib/python2.6/site-packages/mysql/connector/connection.py", line 356, in connect
    self._open_connection()
  File "/usr/lib/python2.6/site-packages/mysql/connector/connection.py", line 319, in _open_connection
    self._socket.open_connection()
  File "/usr/lib/python2.6/site-packages/mysql/connector/network.py", line 393, in open_connection
    errno=2003, values=(self.server_host, msg))
InterfaceError: 2003: Can't connect to MySQL server on 'localhost' (111)
[2013-08-16 03:01:01,587]CRITICAL: The process is terminated with an exception.
Traceback (most recent call last):
  File "/home/cdnlab-gnp/gnp-deploy/obtain_ipaddr.py", line 170, in <module>
    autocommit=True)
  File "/usr/lib/python2.6/site-packages/mysql/connector/__init__.py", line 44, in Connect
    return MySQLConnection(*args, **kwargs)
  File "/usr/lib/python2.6/site-packages/mysql/connector/connection.py", line 108, in __init__
    self.connect(**kwargs)
  File "/usr/lib/python2.6/site-packages/mysql/connector/connection.py", line 356, in connect
    self._open_connection()
  File "/usr/lib/python2.6/site-packages/mysql/connector/connection.py", line 319, in _open_connection
    self._socket.open_connection()
  File "/usr/lib/python2.6/site-packages/mysql/connector/network.py", line 393, in open_connection
    errno=2003, values=(self.server_host, msg))
InterfaceError: 2003: Can't connect to MySQL server on 'localhost' (111)
[2013-08-16 04:01:01,663]CRITICAL: The process is terminated with an exception.
Traceback (most recent call last):
  File "/home/cdnlab-gnp/gnp-deploy/obtain_ipaddr.py", line 170, in <module>
    autocommit=True)
  File "/usr/lib/python2.6/site-packages/mysql/connector/__init__.py", line 44, in Connect
    return MySQLConnection(*args, **kwargs)
  File "/usr/lib/python2.6/site-packages/mysql/connector/connection.py", line 108, in __init__
    self.connect(**kwargs)
  File "/usr/lib/python2.6/site-packages/mysql/connector/connection.py", line 356, in connect
    self._open_connection()
  File "/usr/lib/python2.6/site-packages/mysql/connector/connection.py", line 319, in _open_connection
    self._socket.open_connection()
  File "/usr/lib/python2.6/site-packages/mysql/connector/network.py", line 393, in open_connection
    errno=2003, values=(self.server_host, msg))
InterfaceError: 2003: Can't connect to MySQL server on 'localhost' (111)
[2013-08-16 05:01:01,245]CRITICAL: The process is terminated with an exception.
Traceback (most recent call last):
  File "/home/cdnlab-gnp/gnp-deploy/obtain_ipaddr.py", line 170, in <module>
    autocommit=True)
  File "/usr/lib/python2.6/site-packages/mysql/connector/__init__.py", line 44, in Connect
    return MySQLConnection(*args, **kwargs)
  File "/usr/lib/python2.6/site-packages/mysql/connector/connection.py", line 108, in __init__
    self.connect(**kwargs)
  File "/usr/lib/python2.6/site-packages/mysql/connector/connection.py", line 356, in connect
    self._open_connection()
  File "/usr/lib/python2.6/site-packages/mysql/connector/connection.py", line 319, in _open_connection
    self._socket.open_connection()
  File "/usr/lib/python2.6/site-packages/mysql/connector/network.py", line 393, in open_connection
    errno=2003, values=(self.server_host, msg))
InterfaceError: 2003: Can't connect to MySQL server on 'localhost' (111)
[2013-08-16 06:01:01,488]CRITICAL: The process is terminated with an exception.
Traceback (most recent call last):
  File "/home/cdnlab-gnp/gnp-deploy/obtain_ipaddr.py", line 170, in <module>
    autocommit=True)
  File "/usr/lib/python2.6/site-packages/mysql/connector/__init__.py", line 44, in Connect
    return MySQLConnection(*args, **kwargs)
  File "/usr/lib/python2.6/site-packages/mysql/connector/connection.py", line 108, in __init__
    self.connect(**kwargs)
  File "/usr/lib/python2.6/site-packages/mysql/connector/connection.py", line 356, in connect
    self._open_connection()
  File "/usr/lib/python2.6/site-packages/mysql/connector/connection.py", line 319, in _open_connection
    self._socket.open_connection()
  File "/usr/lib/python2.6/site-packages/mysql/connector/network.py", line 393, in open_connection
    errno=2003, values=(self.server_host, msg))
InterfaceError: 2003: Can't connect to MySQL server on 'localhost' (111)
[2013-08-16 07:01:01,525]CRITICAL: The process is terminated with an exception.
Traceback (most recent call last):
  File "/home/cdnlab-gnp/gnp-deploy/obtain_ipaddr.py", line 170, in <module>
    autocommit=True)
  File "/usr/lib/python2.6/site-packages/mysql/connector/__init__.py", line 44, in Connect
    return MySQLConnection(*args, **kwargs)
  File "/usr/lib/python2.6/site-packages/mysql/connector/connection.py", line 108, in __init__
    self.connect(**kwargs)
  File "/usr/lib/python2.6/site-packages/mysql/connector/connection.py", line 356, in connect
    self._open_connection()
  File "/usr/lib/python2.6/site-packages/mysql/connector/connection.py", line 319, in _open_connection
    self._socket.open_connection()
  File "/usr/lib/python2.6/site-packages/mysql/connector/network.py", line 393, in open_connection
    errno=2003, values=(self.server_host, msg))
InterfaceError: 2003: Can't connect to MySQL server on 'localhost' (111)
[2013-08-16 08:01:01,126]CRITICAL: The process is terminated with an exception.
Traceback (most recent call last):
  File "/home/cdnlab-gnp/gnp-deploy/obtain_ipaddr.py", line 170, in <module>
    autocommit=True)
  File "/usr/lib/python2.6/site-packages/mysql/connector/__init__.py", line 44, in Connect
    return MySQLConnection(*args, **kwargs)
  File "/usr/lib/python2.6/site-packages/mysql/connector/connection.py", line 108, in __init__
    self.connect(**kwargs)
  File "/usr/lib/python2.6/site-packages/mysql/connector/connection.py", line 356, in connect
    self._open_connection()
  File "/usr/lib/python2.6/site-packages/mysql/connector/connection.py", line 319, in _open_connection
    self._socket.open_connection()
  File "/usr/lib/python2.6/site-packages/mysql/connector/network.py", line 393, in open_connection
    errno=2003, values=(self.server_host, msg))
InterfaceError: 2003: Can't connect to MySQL server on 'localhost' (111)
[2013-08-16 09:01:01,974]CRITICAL: The process is terminated with an exception.
Traceback (most recent call last):
  File "/home/cdnlab-gnp/gnp-deploy/obtain_ipaddr.py", line 170, in <module>
    autocommit=True)
  File "/usr/lib/python2.6/site-packages/mysql/connector/__init__.py", line 44, in Connect
    return MySQLConnection(*args, **kwargs)
  File "/usr/lib/python2.6/site-packages/mysql/connector/connection.py", line 108, in __init__
    self.connect(**kwargs)
  File "/usr/lib/python2.6/site-packages/mysql/connector/connection.py", line 356, in connect
    self._open_connection()
  File "/usr/lib/python2.6/site-packages/mysql/connector/connection.py", line 319, in _open_connection
    self._socket.open_connection()
  File "/usr/lib/python2.6/site-packages/mysql/connector/network.py", line 393, in open_connection
    errno=2003, values=(self.server_host, msg))
InterfaceError: 2003: Can't connect to MySQL server on 'localhost' (111)
[2013-08-16 10:01:02,565]CRITICAL: The process is terminated with an exception.
Traceback (most recent call last):
  File "/home/cdnlab-gnp/gnp-deploy/obtain_ipaddr.py", line 170, in <module>
    autocommit=True)
  File "/usr/lib/python2.6/site-packages/mysql/connector/__init__.py", line 44, in Connect
    return MySQLConnection(*args, **kwargs)
  File "/usr/lib/python2.6/site-packages/mysql/connector/connection.py", line 108, in __init__
    self.connect(**kwargs)
  File "/usr/lib/python2.6/site-packages/mysql/connector/connection.py", line 356, in connect
    self._open_connection()
  File "/usr/lib/python2.6/site-packages/mysql/connector/connection.py", line 319, in _open_connection
    self._socket.open_connection()
  File "/usr/lib/python2.6/site-packages/mysql/connector/network.py", line 393, in open_connection
    errno=2003, values=(self.server_host, msg))
InterfaceError: 2003: Can't connect to MySQL server on 'localhost' (111)
[2013-08-16 11:01:04,923]CRITICAL: The process is terminated with an exception.
Traceback (most recent call last):
  File "/home/cdnlab-gnp/gnp-deploy/obtain_ipaddr.py", line 170, in <module>
    autocommit=True)
  File "/usr/lib/python2.6/site-packages/mysql/connector/__init__.py", line 44, in Connect
    return MySQLConnection(*args, **kwargs)
  File "/usr/lib/python2.6/site-packages/mysql/connector/connection.py", line 108, in __init__
    self.connect(**kwargs)
  File "/usr/lib/python2.6/site-packages/mysql/connector/connection.py", line 356, in connect
    self._open_connection()
  File "/usr/lib/python2.6/site-packages/mysql/connector/connection.py", line 319, in _open_connection
    self._socket.open_connection()
  File "/usr/lib/python2.6/site-packages/mysql/connector/network.py", line 393, in open_connection
    errno=2003, values=(self.server_host, msg))
InterfaceError: 2003: Can't connect to MySQL server on 'localhost' (111)
[2013-08-16 12:01:02,633]CRITICAL: The process is terminated with an exception.
Traceback (most recent call last):
  File "/home/cdnlab-gnp/gnp-deploy/obtain_ipaddr.py", line 170, in <module>
    autocommit=True)
  File "/usr/lib/python2.6/site-packages/mysql/connector/__init__.py", line 44, in Connect
    return MySQLConnection(*args, **kwargs)
  File "/usr/lib/python2.6/site-packages/mysql/connector/connection.py", line 108, in __init__
    self.connect(**kwargs)
  File "/usr/lib/python2.6/site-packages/mysql/connector/connection.py", line 356, in connect
    self._open_connection()
  File "/usr/lib/python2.6/site-packages/mysql/connector/connection.py", line 319, in _open_connection
    self._socket.open_connection()
  File "/usr/lib/python2.6/site-packages/mysql/connector/network.py", line 393, in open_connection
    errno=2003, values=(self.server_host, msg))
InterfaceError: 2003: Can't connect to MySQL server on 'localhost' (111)
[2013-08-16 13:01:01,260]CRITICAL: The process is terminated with an exception.
Traceback (most recent call last):
  File "/home/cdnlab-gnp/gnp-deploy/obtain_ipaddr.py", line 170, in <module>
    autocommit=True)
  File "/usr/lib/python2.6/site-packages/mysql/connector/__init__.py", line 44, in Connect
    return MySQLConnection(*args, **kwargs)
  File "/usr/lib/python2.6/site-packages/mysql/connector/connection.py", line 108, in __init__
    self.connect(**kwargs)
  File "/usr/lib/python2.6/site-packages/mysql/connector/connection.py", line 356, in connect
    self._open_connection()
  File "/usr/lib/python2.6/site-packages/mysql/connector/connection.py", line 319, in _open_connection
    self._socket.open_connection()
  File "/usr/lib/python2.6/site-packages/mysql/connector/network.py", line 393, in open_connection
    errno=2003, values=(self.server_host, msg))
InterfaceError: 2003: Can't connect to MySQL server on 'localhost' (111)
[2013-08-16 14:01:01,471]CRITICAL: The process is terminated with an exception.
Traceback (most recent call last):
  File "/home/cdnlab-gnp/gnp-deploy/obtain_ipaddr.py", line 170, in <module>
    autocommit=True)
  File "/usr/lib/python2.6/site-packages/mysql/connector/__init__.py", line 44, in Connect
    return MySQLConnection(*args, **kwargs)
  File "/usr/lib/python2.6/site-packages/mysql/connector/connection.py", line 108, in __init__
    self.connect(**kwargs)
  File "/usr/lib/python2.6/site-packages/mysql/connector/connection.py", line 356, in connect
    self._open_connection()
  File "/usr/lib/python2.6/site-packages/mysql/connector/connection.py", line 319, in _open_connection
    self._socket.open_connection()
  File "/usr/lib/python2.6/site-packages/mysql/connector/network.py", line 393, in open_connection
    errno=2003, values=(self.server_host, msg))
InterfaceError: 2003: Can't connect to MySQL server on 'localhost' (111)
[2013-08-16 15:01:01,473]CRITICAL: The process is terminated with an exception.
Traceback (most recent call last):
  File "/home/cdnlab-gnp/gnp-deploy/obtain_ipaddr.py", line 170, in <module>
    autocommit=True)
  File "/usr/lib/python2.6/site-packages/mysql/connector/__init__.py", line 44, in Connect
    return MySQLConnection(*args, **kwargs)
  File "/usr/lib/python2.6/site-packages/mysql/connector/connection.py", line 108, in __init__
    self.connect(**kwargs)
  File "/usr/lib/python2.6/site-packages/mysql/connector/connection.py", line 356, in connect
    self._open_connection()
  File "/usr/lib/python2.6/site-packages/mysql/connector/connection.py", line 319, in _open_connection
    self._socket.open_connection()
  File "/usr/lib/python2.6/site-packages/mysql/connector/network.py", line 393, in open_connection
    errno=2003, values=(self.server_host, msg))
InterfaceError: 2003: Can't connect to MySQL server on 'localhost' (111)
[2013-08-16 16:01:01,193]CRITICAL: The process is terminated with an exception.
Traceback (most recent call last):
  File "/home/cdnlab-gnp/gnp-deploy/obtain_ipaddr.py", line 170, in <module>
    autocommit=True)
  File "/usr/lib/python2.6/site-packages/mysql/connector/__init__.py", line 44, in Connect
    return MySQLConnection(*args, **kwargs)
  File "/usr/lib/python2.6/site-packages/mysql/connector/connection.py", line 108, in __init__
    self.connect(**kwargs)
  File "/usr/lib/python2.6/site-packages/mysql/connector/connection.py", line 356, in connect
    self._open_connection()
  File "/usr/lib/python2.6/site-packages/mysql/connector/connection.py", line 319, in _open_connection
    self._socket.open_connection()
  File "/usr/lib/python2.6/site-packages/mysql/connector/network.py", line 393, in open_connection
    errno=2003, values=(self.server_host, msg))
InterfaceError: 2003: Can't connect to MySQL server on 'localhost' (111)
[2013-08-16 17:01:01,731]CRITICAL: The process is terminated with an exception.
Traceback (most recent call last):
  File "/home/cdnlab-gnp/gnp-deploy/obtain_ipaddr.py", line 170, in <module>
    autocommit=True)
  File "/usr/lib/python2.6/site-packages/mysql/connector/__init__.py", line 44, in Connect
    return MySQLConnection(*args, **kwargs)
  File "/usr/lib/python2.6/site-packages/mysql/connector/connection.py", line 108, in __init__
    self.connect(**kwargs)
  File "/usr/lib/python2.6/site-packages/mysql/connector/connection.py", line 356, in connect
    self._open_connection()
  File "/usr/lib/python2.6/site-packages/mysql/connector/connection.py", line 319, in _open_connection
    self._socket.open_connection()
  File "/usr/lib/python2.6/site-packages/mysql/connector/network.py", line 393, in open_connection
    errno=2003, values=(self.server_host, msg))
InterfaceError: 2003: Can't connect to MySQL server on 'localhost' (111)
[2013-08-16 18:01:01,921]CRITICAL: The process is terminated with an exception.
Traceback (most recent call last):
  File "/home/cdnlab-gnp/gnp-deploy/obtain_ipaddr.py", line 170, in <module>
    autocommit=True)
  File "/usr/lib/python2.6/site-packages/mysql/connector/__init__.py", line 44, in Connect
    return MySQLConnection(*args, **kwargs)
  File "/usr/lib/python2.6/site-packages/mysql/connector/connection.py", line 108, in __init__
    self.connect(**kwargs)
  File "/usr/lib/python2.6/site-packages/mysql/connector/connection.py", line 356, in connect
    self._open_connection()
  File "/usr/lib/python2.6/site-packages/mysql/connector/connection.py", line 319, in _open_connection
    self._socket.open_connection()
  File "/usr/lib/python2.6/site-packages/mysql/connector/network.py", line 393, in open_connection
    errno=2003, values=(self.server_host, msg))
InterfaceError: 2003: Can't connect to MySQL server on 'localhost' (111)
[2013-08-16 19:01:01,327]CRITICAL: The process is terminated with an exception.
Traceback (most recent call last):
  File "/home/cdnlab-gnp/gnp-deploy/obtain_ipaddr.py", line 170, in <module>
    autocommit=True)
  File "/usr/lib/python2.6/site-packages/mysql/connector/__init__.py", line 44, in Connect
    return MySQLConnection(*args, **kwargs)
  File "/usr/lib/python2.6/site-packages/mysql/connector/connection.py", line 108, in __init__
    self.connect(**kwargs)
  File "/usr/lib/python2.6/site-packages/mysql/connector/connection.py", line 356, in connect
    self._open_connection()
  File "/usr/lib/python2.6/site-packages/mysql/connector/connection.py", line 319, in _open_connection
    self._socket.open_connection()
  File "/usr/lib/python2.6/site-packages/mysql/connector/network.py", line 393, in open_connection
    errno=2003, values=(self.server_host, msg))
InterfaceError: 2003: Can't connect to MySQL server on 'localhost' (111)
[2013-08-16 20:01:01,632]CRITICAL: The process is terminated with an exception.
Traceback (most recent call last):
  File "/home/cdnlab-gnp/gnp-deploy/obtain_ipaddr.py", line 170, in <module>
    autocommit=True)
  File "/usr/lib/python2.6/site-packages/mysql/connector/__init__.py", line 44, in Connect
    return MySQLConnection(*args, **kwargs)
  File "/usr/lib/python2.6/site-packages/mysql/connector/connection.py", line 108, in __init__
    self.connect(**kwargs)
  File "/usr/lib/python2.6/site-packages/mysql/connector/connection.py", line 356, in connect
    self._open_connection()
  File "/usr/lib/python2.6/site-packages/mysql/connector/connection.py", line 319, in _open_connection
    self._socket.open_connection()
  File "/usr/lib/python2.6/site-packages/mysql/connector/network.py", line 393, in open_connection
    errno=2003, values=(self.server_host, msg))
InterfaceError: 2003: Can't connect to MySQL server on 'localhost' (111)
[2013-08-16 21:01:01,885]CRITICAL: The process is terminated with an exception.
Traceback (most recent call last):
  File "/home/cdnlab-gnp/gnp-deploy/obtain_ipaddr.py", line 170, in <module>
    autocommit=True)
  File "/usr/lib/python2.6/site-packages/mysql/connector/__init__.py", line 44, in Connect
    return MySQLConnection(*args, **kwargs)
  File "/usr/lib/python2.6/site-packages/mysql/connector/connection.py", line 108, in __init__
    self.connect(**kwargs)
  File "/usr/lib/python2.6/site-packages/mysql/connector/connection.py", line 356, in connect
    self._open_connection()
  File "/usr/lib/python2.6/site-packages/mysql/connector/connection.py", line 319, in _open_connection
    self._socket.open_connection()
  File "/usr/lib/python2.6/site-packages/mysql/connector/network.py", line 393, in open_connection
    errno=2003, values=(self.server_host, msg))
InterfaceError: 2003: Can't connect to MySQL server on 'localhost' (111)
[2013-08-16 22:01:01,764]CRITICAL: The process is terminated with an exception.
Traceback (most recent call last):
  File "/home/cdnlab-gnp/gnp-deploy/obtain_ipaddr.py", line 170, in <module>
    autocommit=True)
  File "/usr/lib/python2.6/site-packages/mysql/connector/__init__.py", line 44, in Connect
    return MySQLConnection(*args, **kwargs)
  File "/usr/lib/python2.6/site-packages/mysql/connector/connection.py", line 108, in __init__
    self.connect(**kwargs)
  File "/usr/lib/python2.6/site-packages/mysql/connector/connection.py", line 356, in connect
    self._open_connection()
  File "/usr/lib/python2.6/site-packages/mysql/connector/connection.py", line 319, in _open_connection
    self._socket.open_connection()
  File "/usr/lib/python2.6/site-packages/mysql/connector/network.py", line 393, in open_connection
    errno=2003, values=(self.server_host, msg))
InterfaceError: 2003: Can't connect to MySQL server on 'localhost' (111)
[2013-08-16 23:01:01,877]CRITICAL: The process is terminated with an exception.
Traceback (most recent call last):
  File "/home/cdnlab-gnp/gnp-deploy/obtain_ipaddr.py", line 170, in <module>
    autocommit=True)
  File "/usr/lib/python2.6/site-packages/mysql/connector/__init__.py", line 44, in Connect
    return MySQLConnection(*args, **kwargs)
  File "/usr/lib/python2.6/site-packages/mysql/connector/connection.py", line 108, in __init__
    self.connect(**kwargs)
  File "/usr/lib/python2.6/site-packages/mysql/connector/connection.py", line 356, in connect
    self._open_connection()
  File "/usr/lib/python2.6/site-packages/mysql/connector/connection.py", line 319, in _open_connection
    self._socket.open_connection()
  File "/usr/lib/python2.6/site-packages/mysql/connector/network.py", line 393, in open_connection
    errno=2003, values=(self.server_host, msg))
InterfaceError: 2003: Can't connect to MySQL server on 'localhost' (111)
[2013-08-17 00:01:01,968]CRITICAL: The process is terminated with an exception.
Traceback (most recent call last):
  File "/home/cdnlab-gnp/gnp-deploy/obtain_ipaddr.py", line 170, in <module>
    autocommit=True)
  File "/usr/lib/python2.6/site-packages/mysql/connector/__init__.py", line 44, in Connect
    return MySQLConnection(*args, **kwargs)
  File "/usr/lib/python2.6/site-packages/mysql/connector/connection.py", line 108, in __init__
    self.connect(**kwargs)
  File "/usr/lib/python2.6/site-packages/mysql/connector/connection.py", line 356, in connect
    self._open_connection()
  File "/usr/lib/python2.6/site-packages/mysql/connector/connection.py", line 319, in _open_connection
    self._socket.open_connection()
  File "/usr/lib/python2.6/site-packages/mysql/connector/network.py", line 393, in open_connection
    errno=2003, values=(self.server_host, msg))
InterfaceError: 2003: Can't connect to MySQL server on 'localhost' (111)
[2013-08-17 01:01:01,648]CRITICAL: The process is terminated with an exception.
Traceback (most recent call last):
  File "/home/cdnlab-gnp/gnp-deploy/obtain_ipaddr.py", line 170, in <module>
    autocommit=True)
  File "/usr/lib/python2.6/site-packages/mysql/connector/__init__.py", line 44, in Connect
    return MySQLConnection(*args, **kwargs)
  File "/usr/lib/python2.6/site-packages/mysql/connector/connection.py", line 108, in __init__
    self.connect(**kwargs)
  File "/usr/lib/python2.6/site-packages/mysql/connector/connection.py", line 356, in connect
    self._open_connection()
  File "/usr/lib/python2.6/site-packages/mysql/connector/connection.py", line 319, in _open_connection
    self._socket.open_connection()
  File "/usr/lib/python2.6/site-packages/mysql/connector/network.py", line 393, in open_connection
    errno=2003, values=(self.server_host, msg))
InterfaceError: 2003: Can't connect to MySQL server on 'localhost' (111)
[2013-08-17 02:01:01,980]CRITICAL: The process is terminated with an exception.
Traceback (most recent call last):
  File "/home/cdnlab-gnp/gnp-deploy/obtain_ipaddr.py", line 170, in <module>
    autocommit=True)
  File "/usr/lib/python2.6/site-packages/mysql/connector/__init__.py", line 44, in Connect
    return MySQLConnection(*args, **kwargs)
  File "/usr/lib/python2.6/site-packages/mysql/connector/connection.py", line 108, in __init__
    self.connect(**kwargs)
  File "/usr/lib/python2.6/site-packages/mysql/connector/connection.py", line 356, in connect
    self._open_connection()
  File "/usr/lib/python2.6/site-packages/mysql/connector/connection.py", line 319, in _open_connection
    self._socket.open_connection()
  File "/usr/lib/python2.6/site-packages/mysql/connector/network.py", line 393, in open_connection
    errno=2003, values=(self.server_host, msg))
InterfaceError: 2003: Can't connect to MySQL server on 'localhost' (111)
[2013-08-17 03:01:01,280]CRITICAL: The process is terminated with an exception.
Traceback (most recent call last):
  File "/home/cdnlab-gnp/gnp-deploy/obtain_ipaddr.py", line 170, in <module>
    autocommit=True)
  File "/usr/lib/python2.6/site-packages/mysql/connector/__init__.py", line 44, in Connect
    return MySQLConnection(*args, **kwargs)
  File "/usr/lib/python2.6/site-packages/mysql/connector/connection.py", line 108, in __init__
    self.connect(**kwargs)
  File "/usr/lib/python2.6/site-packages/mysql/connector/connection.py", line 356, in connect
    self._open_connection()
  File "/usr/lib/python2.6/site-packages/mysql/connector/connection.py", line 319, in _open_connection
    self._socket.open_connection()
  File "/usr/lib/python2.6/site-packages/mysql/connector/network.py", line 393, in open_connection
    errno=2003, values=(self.server_host, msg))
InterfaceError: 2003: Can't connect to MySQL server on 'localhost' (111)
[2013-08-17 04:01:01,705]CRITICAL: The process is terminated with an exception.
Traceback (most recent call last):
  File "/home/cdnlab-gnp/gnp-deploy/obtain_ipaddr.py", line 170, in <module>
    autocommit=True)
  File "/usr/lib/python2.6/site-packages/mysql/connector/__init__.py", line 44, in Connect
    return MySQLConnection(*args, **kwargs)
  File "/usr/lib/python2.6/site-packages/mysql/connector/connection.py", line 108, in __init__
    self.connect(**kwargs)
  File "/usr/lib/python2.6/site-packages/mysql/connector/connection.py", line 356, in connect
    self._open_connection()
  File "/usr/lib/python2.6/site-packages/mysql/connector/connection.py", line 319, in _open_connection
    self._socket.open_connection()
  File "/usr/lib/python2.6/site-packages/mysql/connector/network.py", line 393, in open_connection
    errno=2003, values=(self.server_host, msg))
InterfaceError: 2003: Can't connect to MySQL server on 'localhost' (111)
[2013-08-17 05:01:01,321]CRITICAL: The process is terminated with an exception.
Traceback (most recent call last):
  File "/home/cdnlab-gnp/gnp-deploy/obtain_ipaddr.py", line 170, in <module>
    autocommit=True)
  File "/usr/lib/python2.6/site-packages/mysql/connector/__init__.py", line 44, in Connect
    return MySQLConnection(*args, **kwargs)
  File "/usr/lib/python2.6/site-packages/mysql/connector/connection.py", line 108, in __init__
    self.connect(**kwargs)
  File "/usr/lib/python2.6/site-packages/mysql/connector/connection.py", line 356, in connect
    self._open_connection()
  File "/usr/lib/python2.6/site-packages/mysql/connector/connection.py", line 319, in _open_connection
    self._socket.open_connection()
  File "/usr/lib/python2.6/site-packages/mysql/connector/network.py", line 393, in open_connection
    errno=2003, values=(self.server_host, msg))
InterfaceError: 2003: Can't connect to MySQL server on 'localhost' (111)
[2013-08-17 06:01:01,900]CRITICAL: The process is terminated with an exception.
Traceback (most recent call last):
  File "/home/cdnlab-gnp/gnp-deploy/obtain_ipaddr.py", line 170, in <module>
    autocommit=True)
  File "/usr/lib/python2.6/site-packages/mysql/connector/__init__.py", line 44, in Connect
    return MySQLConnection(*args, **kwargs)
  File "/usr/lib/python2.6/site-packages/mysql/connector/connection.py", line 108, in __init__
    self.connect(**kwargs)
  File "/usr/lib/python2.6/site-packages/mysql/connector/connection.py", line 356, in connect
    self._open_connection()
  File "/usr/lib/python2.6/site-packages/mysql/connector/connection.py", line 319, in _open_connection
    self._socket.open_connection()
  File "/usr/lib/python2.6/site-packages/mysql/connector/network.py", line 393, in open_connection
    errno=2003, values=(self.server_host, msg))
InterfaceError: 2003: Can't connect to MySQL server on 'localhost' (111)
[2013-08-17 07:01:01,687]CRITICAL: The process is terminated with an exception.
Traceback (most recent call last):
  File "/home/cdnlab-gnp/gnp-deploy/obtain_ipaddr.py", line 170, in <module>
    autocommit=True)
  File "/usr/lib/python2.6/site-packages/mysql/connector/__init__.py", line 44, in Connect
    return MySQLConnection(*args, **kwargs)
  File "/usr/lib/python2.6/site-packages/mysql/connector/connection.py", line 108, in __init__
    self.connect(**kwargs)
  File "/usr/lib/python2.6/site-packages/mysql/connector/connection.py", line 356, in connect
    self._open_connection()
  File "/usr/lib/python2.6/site-packages/mysql/connector/connection.py", line 319, in _open_connection
    self._socket.open_connection()
  File "/usr/lib/python2.6/site-packages/mysql/connector/network.py", line 393, in open_connection
    errno=2003, values=(self.server_host, msg))
InterfaceError: 2003: Can't connect to MySQL server on 'localhost' (111)
[2013-08-17 08:01:01,160]CRITICAL: The process is terminated with an exception.
Traceback (most recent call last):
  File "/home/cdnlab-gnp/gnp-deploy/obtain_ipaddr.py", line 170, in <module>
    autocommit=True)
  File "/usr/lib/python2.6/site-packages/mysql/connector/__init__.py", line 44, in Connect
    return MySQLConnection(*args, **kwargs)
  File "/usr/lib/python2.6/site-packages/mysql/connector/connection.py", line 108, in __init__
    self.connect(**kwargs)
  File "/usr/lib/python2.6/site-packages/mysql/connector/connection.py", line 356, in connect
    self._open_connection()
  File "/usr/lib/python2.6/site-packages/mysql/connector/connection.py", line 319, in _open_connection
    self._socket.open_connection()
  File "/usr/lib/python2.6/site-packages/mysql/connector/network.py", line 393, in open_connection
    errno=2003, values=(self.server_host, msg))
InterfaceError: 2003: Can't connect to MySQL server on 'localhost' (111)
[2013-08-17 09:01:01,781]CRITICAL: The process is terminated with an exception.
Traceback (most recent call last):
  File "/home/cdnlab-gnp/gnp-deploy/obtain_ipaddr.py", line 170, in <module>
    autocommit=True)
  File "/usr/lib/python2.6/site-packages/mysql/connector/__init__.py", line 44, in Connect
    return MySQLConnection(*args, **kwargs)
  File "/usr/lib/python2.6/site-packages/mysql/connector/connection.py", line 108, in __init__
    self.connect(**kwargs)
  File "/usr/lib/python2.6/site-packages/mysql/connector/connection.py", line 356, in connect
    self._open_connection()
  File "/usr/lib/python2.6/site-packages/mysql/connector/connection.py", line 319, in _open_connection
    self._socket.open_connection()
  File "/usr/lib/python2.6/site-packages/mysql/connector/network.py", line 393, in open_connection
    errno=2003, values=(self.server_host, msg))
InterfaceError: 2003: Can't connect to MySQL server on 'localhost' (111)
[2013-08-17 10:01:01,836]CRITICAL: The process is terminated with an exception.
Traceback (most recent call last):
  File "/home/cdnlab-gnp/gnp-deploy/obtain_ipaddr.py", line 170, in <module>
    autocommit=True)
  File "/usr/lib/python2.6/site-packages/mysql/connector/__init__.py", line 44, in Connect
    return MySQLConnection(*args, **kwargs)
  File "/usr/lib/python2.6/site-packages/mysql/connector/connection.py", line 108, in __init__
    self.connect(**kwargs)
  File "/usr/lib/python2.6/site-packages/mysql/connector/connection.py", line 356, in connect
    self._open_connection()
  File "/usr/lib/python2.6/site-packages/mysql/connector/connection.py", line 319, in _open_connection
    self._socket.open_connection()
  File "/usr/lib/python2.6/site-packages/mysql/connector/network.py", line 393, in open_connection
    errno=2003, values=(self.server_host, msg))
InterfaceError: 2003: Can't connect to MySQL server on 'localhost' (111)
[2013-08-17 11:01:01,861]CRITICAL: The process is terminated with an exception.
Traceback (most recent call last):
  File "/home/cdnlab-gnp/gnp-deploy/obtain_ipaddr.py", line 170, in <module>
    autocommit=True)
  File "/usr/lib/python2.6/site-packages/mysql/connector/__init__.py", line 44, in Connect
    return MySQLConnection(*args, **kwargs)
  File "/usr/lib/python2.6/site-packages/mysql/connector/connection.py", line 108, in __init__
    self.connect(**kwargs)
  File "/usr/lib/python2.6/site-packages/mysql/connector/connection.py", line 356, in connect
    self._open_connection()
  File "/usr/lib/python2.6/site-packages/mysql/connector/connection.py", line 319, in _open_connection
    self._socket.open_connection()
  File "/usr/lib/python2.6/site-packages/mysql/connector/network.py", line 393, in open_connection
    errno=2003, values=(self.server_host, msg))
InterfaceError: 2003: Can't connect to MySQL server on 'localhost' (111)
[2013-08-17 12:01:01,818]CRITICAL: The process is terminated with an exception.
Traceback (most recent call last):
  File "/home/cdnlab-gnp/gnp-deploy/obtain_ipaddr.py", line 170, in <module>
    autocommit=True)
  File "/usr/lib/python2.6/site-packages/mysql/connector/__init__.py", line 44, in Connect
    return MySQLConnection(*args, **kwargs)
  File "/usr/lib/python2.6/site-packages/mysql/connector/connection.py", line 108, in __init__
    self.connect(**kwargs)
  File "/usr/lib/python2.6/site-packages/mysql/connector/connection.py", line 356, in connect
    self._open_connection()
  File "/usr/lib/python2.6/site-packages/mysql/connector/connection.py", line 319, in _open_connection
    self._socket.open_connection()
  File "/usr/lib/python2.6/site-packages/mysql/connector/network.py", line 393, in open_connection
    errno=2003, values=(self.server_host, msg))
InterfaceError: 2003: Can't connect to MySQL server on 'localhost' (111)
[2013-08-17 13:01:01,746]CRITICAL: The process is terminated with an exception.
Traceback (most recent call last):
  File "/home/cdnlab-gnp/gnp-deploy/obtain_ipaddr.py", line 170, in <module>
    autocommit=True)
  File "/usr/lib/python2.6/site-packages/mysql/connector/__init__.py", line 44, in Connect
    return MySQLConnection(*args, **kwargs)
  File "/usr/lib/python2.6/site-packages/mysql/connector/connection.py", line 108, in __init__
    self.connect(**kwargs)
  File "/usr/lib/python2.6/site-packages/mysql/connector/connection.py", line 356, in connect
    self._open_connection()
  File "/usr/lib/python2.6/site-packages/mysql/connector/connection.py", line 319, in _open_connection
    self._socket.open_connection()
  File "/usr/lib/python2.6/site-packages/mysql/connector/network.py", line 393, in open_connection
    errno=2003, values=(self.server_host, msg))
InterfaceError: 2003: Can't connect to MySQL server on 'localhost' (111)
[2013-08-17 14:01:01,935]CRITICAL: The process is terminated with an exception.
Traceback (most recent call last):
  File "/home/cdnlab-gnp/gnp-deploy/obtain_ipaddr.py", line 170, in <module>
    autocommit=True)
  File "/usr/lib/python2.6/site-packages/mysql/connector/__init__.py", line 44, in Connect
    return MySQLConnection(*args, **kwargs)
  File "/usr/lib/python2.6/site-packages/mysql/connector/connection.py", line 108, in __init__
    self.connect(**kwargs)
  File "/usr/lib/python2.6/site-packages/mysql/connector/connection.py", line 356, in connect
    self._open_connection()
  File "/usr/lib/python2.6/site-packages/mysql/connector/connection.py", line 319, in _open_connection
    self._socket.open_connection()
  File "/usr/lib/python2.6/site-packages/mysql/connector/network.py", line 393, in open_connection
    errno=2003, values=(self.server_host, msg))
InterfaceError: 2003: Can't connect to MySQL server on 'localhost' (111)
[2013-08-17 15:01:01,544]CRITICAL: The process is terminated with an exception.
Traceback (most recent call last):
  File "/home/cdnlab-gnp/gnp-deploy/obtain_ipaddr.py", line 170, in <module>
    autocommit=True)
  File "/usr/lib/python2.6/site-packages/mysql/connector/__init__.py", line 44, in Connect
    return MySQLConnection(*args, **kwargs)
  File "/usr/lib/python2.6/site-packages/mysql/connector/connection.py", line 108, in __init__
    self.connect(**kwargs)
  File "/usr/lib/python2.6/site-packages/mysql/connector/connection.py", line 356, in connect
    self._open_connection()
  File "/usr/lib/python2.6/site-packages/mysql/connector/connection.py", line 319, in _open_connection
    self._socket.open_connection()
  File "/usr/lib/python2.6/site-packages/mysql/connector/network.py", line 393, in open_connection
    errno=2003, values=(self.server_host, msg))
InterfaceError: 2003: Can't connect to MySQL server on 'localhost' (111)
[2013-08-17 16:01:01,827]CRITICAL: The process is terminated with an exception.
Traceback (most recent call last):
  File "/home/cdnlab-gnp/gnp-deploy/obtain_ipaddr.py", line 170, in <module>
    autocommit=True)
  File "/usr/lib/python2.6/site-packages/mysql/connector/__init__.py", line 44, in Connect
    return MySQLConnection(*args, **kwargs)
  File "/usr/lib/python2.6/site-packages/mysql/connector/connection.py", line 108, in __init__
    self.connect(**kwargs)
  File "/usr/lib/python2.6/site-packages/mysql/connector/connection.py", line 356, in connect
    self._open_connection()
  File "/usr/lib/python2.6/site-packages/mysql/connector/connection.py", line 319, in _open_connection
    self._socket.open_connection()
  File "/usr/lib/python2.6/site-packages/mysql/connector/network.py", line 393, in open_connection
    errno=2003, values=(self.server_host, msg))
InterfaceError: 2003: Can't connect to MySQL server on 'localhost' (111)
[2013-08-17 17:01:01,423]CRITICAL: The process is terminated with an exception.
Traceback (most recent call last):
  File "/home/cdnlab-gnp/gnp-deploy/obtain_ipaddr.py", line 170, in <module>
    autocommit=True)
  File "/usr/lib/python2.6/site-packages/mysql/connector/__init__.py", line 44, in Connect
    return MySQLConnection(*args, **kwargs)
  File "/usr/lib/python2.6/site-packages/mysql/connector/connection.py", line 108, in __init__
    self.connect(**kwargs)
  File "/usr/lib/python2.6/site-packages/mysql/connector/connection.py", line 356, in connect
    self._open_connection()
  File "/usr/lib/python2.6/site-packages/mysql/connector/connection.py", line 319, in _open_connection
    self._socket.open_connection()
  File "/usr/lib/python2.6/site-packages/mysql/connector/network.py", line 393, in open_connection
    errno=2003, values=(self.server_host, msg))
InterfaceError: 2003: Can't connect to MySQL server on 'localhost' (111)
[2013-08-17 18:01:01,533]CRITICAL: The process is terminated with an exception.
Traceback (most recent call last):
  File "/home/cdnlab-gnp/gnp-deploy/obtain_ipaddr.py", line 170, in <module>
    autocommit=True)
  File "/usr/lib/python2.6/site-packages/mysql/connector/__init__.py", line 44, in Connect
    return MySQLConnection(*args, **kwargs)
  File "/usr/lib/python2.6/site-packages/mysql/connector/connection.py", line 108, in __init__
    self.connect(**kwargs)
  File "/usr/lib/python2.6/site-packages/mysql/connector/connection.py", line 356, in connect
    self._open_connection()
  File "/usr/lib/python2.6/site-packages/mysql/connector/connection.py", line 319, in _open_connection
    self._socket.open_connection()
  File "/usr/lib/python2.6/site-packages/mysql/connector/network.py", line 393, in open_connection
    errno=2003, values=(self.server_host, msg))
InterfaceError: 2003: Can't connect to MySQL server on 'localhost' (111)
[2013-08-17 19:01:02,097]CRITICAL: The process is terminated with an exception.
Traceback (most recent call last):
  File "/home/cdnlab-gnp/gnp-deploy/obtain_ipaddr.py", line 170, in <module>
    autocommit=True)
  File "/usr/lib/python2.6/site-packages/mysql/connector/__init__.py", line 44, in Connect
    return MySQLConnection(*args, **kwargs)
  File "/usr/lib/python2.6/site-packages/mysql/connector/connection.py", line 108, in __init__
    self.connect(**kwargs)
  File "/usr/lib/python2.6/site-packages/mysql/connector/connection.py", line 356, in connect
    self._open_connection()
  File "/usr/lib/python2.6/site-packages/mysql/connector/connection.py", line 319, in _open_connection
    self._socket.open_connection()
  File "/usr/lib/python2.6/site-packages/mysql/connector/network.py", line 393, in open_connection
    errno=2003, values=(self.server_host, msg))
InterfaceError: 2003: Can't connect to MySQL server on 'localhost' (111)
[2013-08-17 20:01:01,768]CRITICAL: The process is terminated with an exception.
Traceback (most recent call last):
  File "/home/cdnlab-gnp/gnp-deploy/obtain_ipaddr.py", line 170, in <module>
    autocommit=True)
  File "/usr/lib/python2.6/site-packages/mysql/connector/__init__.py", line 44, in Connect
    return MySQLConnection(*args, **kwargs)
  File "/usr/lib/python2.6/site-packages/mysql/connector/connection.py", line 108, in __init__
    self.connect(**kwargs)
  File "/usr/lib/python2.6/site-packages/mysql/connector/connection.py", line 356, in connect
    self._open_connection()
  File "/usr/lib/python2.6/site-packages/mysql/connector/connection.py", line 319, in _open_connection
    self._socket.open_connection()
  File "/usr/lib/python2.6/site-packages/mysql/connector/network.py", line 393, in open_connection
    errno=2003, values=(self.server_host, msg))
InterfaceError: 2003: Can't connect to MySQL server on 'localhost' (111)
[2013-08-17 21:01:01,721]CRITICAL: The process is terminated with an exception.
Traceback (most recent call last):
  File "/home/cdnlab-gnp/gnp-deploy/obtain_ipaddr.py", line 170, in <module>
    autocommit=True)
  File "/usr/lib/python2.6/site-packages/mysql/connector/__init__.py", line 44, in Connect
    return MySQLConnection(*args, **kwargs)
  File "/usr/lib/python2.6/site-packages/mysql/connector/connection.py", line 108, in __init__
    self.connect(**kwargs)
  File "/usr/lib/python2.6/site-packages/mysql/connector/connection.py", line 356, in connect
    self._open_connection()
  File "/usr/lib/python2.6/site-packages/mysql/connector/connection.py", line 319, in _open_connection
    self._socket.open_connection()
  File "/usr/lib/python2.6/site-packages/mysql/connector/network.py", line 393, in open_connection
    errno=2003, values=(self.server_host, msg))
InterfaceError: 2003: Can't connect to MySQL server on 'localhost' (111)
[2013-08-17 22:01:01,822]CRITICAL: The process is terminated with an exception.
Traceback (most recent call last):
  File "/home/cdnlab-gnp/gnp-deploy/obtain_ipaddr.py", line 170, in <module>
    autocommit=True)
  File "/usr/lib/python2.6/site-packages/mysql/connector/__init__.py", line 44, in Connect
    return MySQLConnection(*args, **kwargs)
  File "/usr/lib/python2.6/site-packages/mysql/connector/connection.py", line 108, in __init__
    self.connect(**kwargs)
  File "/usr/lib/python2.6/site-packages/mysql/connector/connection.py", line 356, in connect
    self._open_connection()
  File "/usr/lib/python2.6/site-packages/mysql/connector/connection.py", line 319, in _open_connection
    self._socket.open_connection()
  File "/usr/lib/python2.6/site-packages/mysql/connector/network.py", line 393, in open_connection
    errno=2003, values=(self.server_host, msg))
InterfaceError: 2003: Can't connect to MySQL server on 'localhost' (111)
[2013-08-17 23:01:01,561]CRITICAL: The process is terminated with an exception.
Traceback (most recent call last):
  File "/home/cdnlab-gnp/gnp-deploy/obtain_ipaddr.py", line 170, in <module>
    autocommit=True)
  File "/usr/lib/python2.6/site-packages/mysql/connector/__init__.py", line 44, in Connect
    return MySQLConnection(*args, **kwargs)
  File "/usr/lib/python2.6/site-packages/mysql/connector/connection.py", line 108, in __init__
    self.connect(**kwargs)
  File "/usr/lib/python2.6/site-packages/mysql/connector/connection.py", line 356, in connect
    self._open_connection()
  File "/usr/lib/python2.6/site-packages/mysql/connector/connection.py", line 319, in _open_connection
    self._socket.open_connection()
  File "/usr/lib/python2.6/site-packages/mysql/connector/network.py", line 393, in open_connection
    errno=2003, values=(self.server_host, msg))
InterfaceError: 2003: Can't connect to MySQL server on 'localhost' (111)
[2013-08-18 00:01:01,192]CRITICAL: The process is terminated with an exception.
Traceback (most recent call last):
  File "/home/cdnlab-gnp/gnp-deploy/obtain_ipaddr.py", line 170, in <module>
    autocommit=True)
  File "/usr/lib/python2.6/site-packages/mysql/connector/__init__.py", line 44, in Connect
    return MySQLConnection(*args, **kwargs)
  File "/usr/lib/python2.6/site-packages/mysql/connector/connection.py", line 108, in __init__
    self.connect(**kwargs)
  File "/usr/lib/python2.6/site-packages/mysql/connector/connection.py", line 356, in connect
    self._open_connection()
  File "/usr/lib/python2.6/site-packages/mysql/connector/connection.py", line 319, in _open_connection
    self._socket.open_connection()
  File "/usr/lib/python2.6/site-packages/mysql/connector/network.py", line 393, in open_connection
    errno=2003, values=(self.server_host, msg))
InterfaceError: 2003: Can't connect to MySQL server on 'localhost' (111)
[2013-08-18 01:01:01,749]CRITICAL: The process is terminated with an exception.
Traceback (most recent call last):
  File "/home/cdnlab-gnp/gnp-deploy/obtain_ipaddr.py", line 170, in <module>
    autocommit=True)
  File "/usr/lib/python2.6/site-packages/mysql/connector/__init__.py", line 44, in Connect
    return MySQLConnection(*args, **kwargs)
  File "/usr/lib/python2.6/site-packages/mysql/connector/connection.py", line 108, in __init__
    self.connect(**kwargs)
  File "/usr/lib/python2.6/site-packages/mysql/connector/connection.py", line 356, in connect
    self._open_connection()
  File "/usr/lib/python2.6/site-packages/mysql/connector/connection.py", line 319, in _open_connection
    self._socket.open_connection()
  File "/usr/lib/python2.6/site-packages/mysql/connector/network.py", line 393, in open_connection
    errno=2003, values=(self.server_host, msg))
InterfaceError: 2003: Can't connect to MySQL server on 'localhost' (111)
[2013-08-18 02:01:02,053]CRITICAL: The process is terminated with an exception.
Traceback (most recent call last):
  File "/home/cdnlab-gnp/gnp-deploy/obtain_ipaddr.py", line 170, in <module>
    autocommit=True)
  File "/usr/lib/python2.6/site-packages/mysql/connector/__init__.py", line 44, in Connect
    return MySQLConnection(*args, **kwargs)
  File "/usr/lib/python2.6/site-packages/mysql/connector/connection.py", line 108, in __init__
    self.connect(**kwargs)
  File "/usr/lib/python2.6/site-packages/mysql/connector/connection.py", line 356, in connect
    self._open_connection()
  File "/usr/lib/python2.6/site-packages/mysql/connector/connection.py", line 319, in _open_connection
    self._socket.open_connection()
  File "/usr/lib/python2.6/site-packages/mysql/connector/network.py", line 393, in open_connection
    errno=2003, values=(self.server_host, msg))
InterfaceError: 2003: Can't connect to MySQL server on 'localhost' (111)
[2013-08-18 03:01:01,881]CRITICAL: The process is terminated with an exception.
Traceback (most recent call last):
  File "/home/cdnlab-gnp/gnp-deploy/obtain_ipaddr.py", line 170, in <module>
    autocommit=True)
  File "/usr/lib/python2.6/site-packages/mysql/connector/__init__.py", line 44, in Connect
    return MySQLConnection(*args, **kwargs)
  File "/usr/lib/python2.6/site-packages/mysql/connector/connection.py", line 108, in __init__
    self.connect(**kwargs)
  File "/usr/lib/python2.6/site-packages/mysql/connector/connection.py", line 356, in connect
    self._open_connection()
  File "/usr/lib/python2.6/site-packages/mysql/connector/connection.py", line 319, in _open_connection
    self._socket.open_connection()
  File "/usr/lib/python2.6/site-packages/mysql/connector/network.py", line 393, in open_connection
    errno=2003, values=(self.server_host, msg))
InterfaceError: 2003: Can't connect to MySQL server on 'localhost' (111)
[2013-08-18 04:01:01,709]CRITICAL: The process is terminated with an exception.
Traceback (most recent call last):
  File "/home/cdnlab-gnp/gnp-deploy/obtain_ipaddr.py", line 170, in <module>
    autocommit=True)
  File "/usr/lib/python2.6/site-packages/mysql/connector/__init__.py", line 44, in Connect
    return MySQLConnection(*args, **kwargs)
  File "/usr/lib/python2.6/site-packages/mysql/connector/connection.py", line 108, in __init__
    self.connect(**kwargs)
  File "/usr/lib/python2.6/site-packages/mysql/connector/connection.py", line 356, in connect
    self._open_connection()
  File "/usr/lib/python2.6/site-packages/mysql/connector/connection.py", line 319, in _open_connection
    self._socket.open_connection()
  File "/usr/lib/python2.6/site-packages/mysql/connector/network.py", line 393, in open_connection
    errno=2003, values=(self.server_host, msg))
InterfaceError: 2003: Can't connect to MySQL server on 'localhost' (111)
[2013-08-18 05:01:01,095]CRITICAL: The process is terminated with an exception.
Traceback (most recent call last):
  File "/home/cdnlab-gnp/gnp-deploy/obtain_ipaddr.py", line 170, in <module>
    autocommit=True)
  File "/usr/lib/python2.6/site-packages/mysql/connector/__init__.py", line 44, in Connect
    return MySQLConnection(*args, **kwargs)
  File "/usr/lib/python2.6/site-packages/mysql/connector/connection.py", line 108, in __init__
    self.connect(**kwargs)
  File "/usr/lib/python2.6/site-packages/mysql/connector/connection.py", line 356, in connect
    self._open_connection()
  File "/usr/lib/python2.6/site-packages/mysql/connector/connection.py", line 319, in _open_connection
    self._socket.open_connection()
  File "/usr/lib/python2.6/site-packages/mysql/connector/network.py", line 393, in open_connection
    errno=2003, values=(self.server_host, msg))
InterfaceError: 2003: Can't connect to MySQL server on 'localhost' (111)
[2013-08-18 06:01:01,104]CRITICAL: The process is terminated with an exception.
Traceback (most recent call last):
  File "/home/cdnlab-gnp/gnp-deploy/obtain_ipaddr.py", line 170, in <module>
    autocommit=True)
  File "/usr/lib/python2.6/site-packages/mysql/connector/__init__.py", line 44, in Connect
    return MySQLConnection(*args, **kwargs)
  File "/usr/lib/python2.6/site-packages/mysql/connector/connection.py", line 108, in __init__
    self.connect(**kwargs)
  File "/usr/lib/python2.6/site-packages/mysql/connector/connection.py", line 356, in connect
    self._open_connection()
  File "/usr/lib/python2.6/site-packages/mysql/connector/connection.py", line 319, in _open_connection
    self._socket.open_connection()
  File "/usr/lib/python2.6/site-packages/mysql/connector/network.py", line 393, in open_connection
    errno=2003, values=(self.server_host, msg))
InterfaceError: 2003: Can't connect to MySQL server on 'localhost' (111)
[2013-08-18 07:01:01,340]CRITICAL: The process is terminated with an exception.
Traceback (most recent call last):
  File "/home/cdnlab-gnp/gnp-deploy/obtain_ipaddr.py", line 170, in <module>
    autocommit=True)
  File "/usr/lib/python2.6/site-packages/mysql/connector/__init__.py", line 44, in Connect
    return MySQLConnection(*args, **kwargs)
  File "/usr/lib/python2.6/site-packages/mysql/connector/connection.py", line 108, in __init__
    self.connect(**kwargs)
  File "/usr/lib/python2.6/site-packages/mysql/connector/connection.py", line 356, in connect
    self._open_connection()
  File "/usr/lib/python2.6/site-packages/mysql/connector/connection.py", line 319, in _open_connection
    self._socket.open_connection()
  File "/usr/lib/python2.6/site-packages/mysql/connector/network.py", line 393, in open_connection
    errno=2003, values=(self.server_host, msg))
InterfaceError: 2003: Can't connect to MySQL server on 'localhost' (111)
[2013-08-18 08:01:01,673]CRITICAL: The process is terminated with an exception.
Traceback (most recent call last):
  File "/home/cdnlab-gnp/gnp-deploy/obtain_ipaddr.py", line 170, in <module>
    autocommit=True)
  File "/usr/lib/python2.6/site-packages/mysql/connector/__init__.py", line 44, in Connect
    return MySQLConnection(*args, **kwargs)
  File "/usr/lib/python2.6/site-packages/mysql/connector/connection.py", line 108, in __init__
    self.connect(**kwargs)
  File "/usr/lib/python2.6/site-packages/mysql/connector/connection.py", line 356, in connect
    self._open_connection()
  File "/usr/lib/python2.6/site-packages/mysql/connector/connection.py", line 319, in _open_connection
    self._socket.open_connection()
  File "/usr/lib/python2.6/site-packages/mysql/connector/network.py", line 393, in open_connection
    errno=2003, values=(self.server_host, msg))
InterfaceError: 2003: Can't connect to MySQL server on 'localhost' (111)
[2013-08-18 09:01:01,262]CRITICAL: The process is terminated with an exception.
Traceback (most recent call last):
  File "/home/cdnlab-gnp/gnp-deploy/obtain_ipaddr.py", line 170, in <module>
    autocommit=True)
  File "/usr/lib/python2.6/site-packages/mysql/connector/__init__.py", line 44, in Connect
    return MySQLConnection(*args, **kwargs)
  File "/usr/lib/python2.6/site-packages/mysql/connector/connection.py", line 108, in __init__
    self.connect(**kwargs)
  File "/usr/lib/python2.6/site-packages/mysql/connector/connection.py", line 356, in connect
    self._open_connection()
  File "/usr/lib/python2.6/site-packages/mysql/connector/connection.py", line 319, in _open_connection
    self._socket.open_connection()
  File "/usr/lib/python2.6/site-packages/mysql/connector/network.py", line 393, in open_connection
    errno=2003, values=(self.server_host, msg))
InterfaceError: 2003: Can't connect to MySQL server on 'localhost' (111)
[2013-08-18 10:01:01,462]CRITICAL: The process is terminated with an exception.
Traceback (most recent call last):
  File "/home/cdnlab-gnp/gnp-deploy/obtain_ipaddr.py", line 170, in <module>
    autocommit=True)
  File "/usr/lib/python2.6/site-packages/mysql/connector/__init__.py", line 44, in Connect
    return MySQLConnection(*args, **kwargs)
  File "/usr/lib/python2.6/site-packages/mysql/connector/connection.py", line 108, in __init__
    self.connect(**kwargs)
  File "/usr/lib/python2.6/site-packages/mysql/connector/connection.py", line 356, in connect
    self._open_connection()
  File "/usr/lib/python2.6/site-packages/mysql/connector/connection.py", line 319, in _open_connection
    self._socket.open_connection()
  File "/usr/lib/python2.6/site-packages/mysql/connector/network.py", line 393, in open_connection
    errno=2003, values=(self.server_host, msg))
InterfaceError: 2003: Can't connect to MySQL server on 'localhost' (111)
[2013-08-18 11:01:01,269]CRITICAL: The process is terminated with an exception.
Traceback (most recent call last):
  File "/home/cdnlab-gnp/gnp-deploy/obtain_ipaddr.py", line 170, in <module>
    autocommit=True)
  File "/usr/lib/python2.6/site-packages/mysql/connector/__init__.py", line 44, in Connect
    return MySQLConnection(*args, **kwargs)
  File "/usr/lib/python2.6/site-packages/mysql/connector/connection.py", line 108, in __init__
    self.connect(**kwargs)
  File "/usr/lib/python2.6/site-packages/mysql/connector/connection.py", line 356, in connect
    self._open_connection()
  File "/usr/lib/python2.6/site-packages/mysql/connector/connection.py", line 319, in _open_connection
    self._socket.open_connection()
  File "/usr/lib/python2.6/site-packages/mysql/connector/network.py", line 393, in open_connection
    errno=2003, values=(self.server_host, msg))
InterfaceError: 2003: Can't connect to MySQL server on 'localhost' (111)
[2013-08-18 12:01:01,603]CRITICAL: The process is terminated with an exception.
Traceback (most recent call last):
  File "/home/cdnlab-gnp/gnp-deploy/obtain_ipaddr.py", line 170, in <module>
    autocommit=True)
  File "/usr/lib/python2.6/site-packages/mysql/connector/__init__.py", line 44, in Connect
    return MySQLConnection(*args, **kwargs)
  File "/usr/lib/python2.6/site-packages/mysql/connector/connection.py", line 108, in __init__
    self.connect(**kwargs)
  File "/usr/lib/python2.6/site-packages/mysql/connector/connection.py", line 356, in connect
    self._open_connection()
  File "/usr/lib/python2.6/site-packages/mysql/connector/connection.py", line 319, in _open_connection
    self._socket.open_connection()
  File "/usr/lib/python2.6/site-packages/mysql/connector/network.py", line 393, in open_connection
    errno=2003, values=(self.server_host, msg))
InterfaceError: 2003: Can't connect to MySQL server on 'localhost' (111)
[2013-08-18 13:01:01,201]CRITICAL: The process is terminated with an exception.
Traceback (most recent call last):
  File "/home/cdnlab-gnp/gnp-deploy/obtain_ipaddr.py", line 170, in <module>
    autocommit=True)
  File "/usr/lib/python2.6/site-packages/mysql/connector/__init__.py", line 44, in Connect
    return MySQLConnection(*args, **kwargs)
  File "/usr/lib/python2.6/site-packages/mysql/connector/connection.py", line 108, in __init__
    self.connect(**kwargs)
  File "/usr/lib/python2.6/site-packages/mysql/connector/connection.py", line 356, in connect
    self._open_connection()
  File "/usr/lib/python2.6/site-packages/mysql/connector/connection.py", line 319, in _open_connection
    self._socket.open_connection()
  File "/usr/lib/python2.6/site-packages/mysql/connector/network.py", line 393, in open_connection
    errno=2003, values=(self.server_host, msg))
InterfaceError: 2003: Can't connect to MySQL server on 'localhost' (111)
[2013-08-18 14:01:01,177]CRITICAL: The process is terminated with an exception.
Traceback (most recent call last):
  File "/home/cdnlab-gnp/gnp-deploy/obtain_ipaddr.py", line 170, in <module>
    autocommit=True)
  File "/usr/lib/python2.6/site-packages/mysql/connector/__init__.py", line 44, in Connect
    return MySQLConnection(*args, **kwargs)
  File "/usr/lib/python2.6/site-packages/mysql/connector/connection.py", line 108, in __init__
    self.connect(**kwargs)
  File "/usr/lib/python2.6/site-packages/mysql/connector/connection.py", line 356, in connect
    self._open_connection()
  File "/usr/lib/python2.6/site-packages/mysql/connector/connection.py", line 319, in _open_connection
    self._socket.open_connection()
  File "/usr/lib/python2.6/site-packages/mysql/connector/network.py", line 393, in open_connection
    errno=2003, values=(self.server_host, msg))
InterfaceError: 2003: Can't connect to MySQL server on 'localhost' (111)
[2013-08-18 15:01:01,410]CRITICAL: The process is terminated with an exception.
Traceback (most recent call last):
  File "/home/cdnlab-gnp/gnp-deploy/obtain_ipaddr.py", line 170, in <module>
    autocommit=True)
  File "/usr/lib/python2.6/site-packages/mysql/connector/__init__.py", line 44, in Connect
    return MySQLConnection(*args, **kwargs)
  File "/usr/lib/python2.6/site-packages/mysql/connector/connection.py", line 108, in __init__
    self.connect(**kwargs)
  File "/usr/lib/python2.6/site-packages/mysql/connector/connection.py", line 356, in connect
    self._open_connection()
  File "/usr/lib/python2.6/site-packages/mysql/connector/connection.py", line 319, in _open_connection
    self._socket.open_connection()
  File "/usr/lib/python2.6/site-packages/mysql/connector/network.py", line 393, in open_connection
    errno=2003, values=(self.server_host, msg))
InterfaceError: 2003: Can't connect to MySQL server on 'localhost' (111)
[2013-08-18 16:01:02,025]CRITICAL: The process is terminated with an exception.
Traceback (most recent call last):
  File "/home/cdnlab-gnp/gnp-deploy/obtain_ipaddr.py", line 170, in <module>
    autocommit=True)
  File "/usr/lib/python2.6/site-packages/mysql/connector/__init__.py", line 44, in Connect
    return MySQLConnection(*args, **kwargs)
  File "/usr/lib/python2.6/site-packages/mysql/connector/connection.py", line 108, in __init__
    self.connect(**kwargs)
  File "/usr/lib/python2.6/site-packages/mysql/connector/connection.py", line 356, in connect
    self._open_connection()
  File "/usr/lib/python2.6/site-packages/mysql/connector/connection.py", line 319, in _open_connection
    self._socket.open_connection()
  File "/usr/lib/python2.6/site-packages/mysql/connector/network.py", line 393, in open_connection
    errno=2003, values=(self.server_host, msg))
InterfaceError: 2003: Can't connect to MySQL server on 'localhost' (111)
[2013-08-18 17:01:01,858]CRITICAL: The process is terminated with an exception.
Traceback (most recent call last):
  File "/home/cdnlab-gnp/gnp-deploy/obtain_ipaddr.py", line 170, in <module>
    autocommit=True)
  File "/usr/lib/python2.6/site-packages/mysql/connector/__init__.py", line 44, in Connect
    return MySQLConnection(*args, **kwargs)
  File "/usr/lib/python2.6/site-packages/mysql/connector/connection.py", line 108, in __init__
    self.connect(**kwargs)
  File "/usr/lib/python2.6/site-packages/mysql/connector/connection.py", line 356, in connect
    self._open_connection()
  File "/usr/lib/python2.6/site-packages/mysql/connector/connection.py", line 319, in _open_connection
    self._socket.open_connection()
  File "/usr/lib/python2.6/site-packages/mysql/connector/network.py", line 393, in open_connection
    errno=2003, values=(self.server_host, msg))
InterfaceError: 2003: Can't connect to MySQL server on 'localhost' (111)
[2013-08-18 18:01:01,164]CRITICAL: The process is terminated with an exception.
Traceback (most recent call last):
  File "/home/cdnlab-gnp/gnp-deploy/obtain_ipaddr.py", line 170, in <module>
    autocommit=True)
  File "/usr/lib/python2.6/site-packages/mysql/connector/__init__.py", line 44, in Connect
    return MySQLConnection(*args, **kwargs)
  File "/usr/lib/python2.6/site-packages/mysql/connector/connection.py", line 108, in __init__
    self.connect(**kwargs)
  File "/usr/lib/python2.6/site-packages/mysql/connector/connection.py", line 356, in connect
    self._open_connection()
  File "/usr/lib/python2.6/site-packages/mysql/connector/connection.py", line 319, in _open_connection
    self._socket.open_connection()
  File "/usr/lib/python2.6/site-packages/mysql/connector/network.py", line 393, in open_connection
    errno=2003, values=(self.server_host, msg))
InterfaceError: 2003: Can't connect to MySQL server on 'localhost' (111)
[2013-08-18 19:01:02,083]CRITICAL: The process is terminated with an exception.
Traceback (most recent call last):
  File "/home/cdnlab-gnp/gnp-deploy/obtain_ipaddr.py", line 170, in <module>
    autocommit=True)
  File "/usr/lib/python2.6/site-packages/mysql/connector/__init__.py", line 44, in Connect
    return MySQLConnection(*args, **kwargs)
  File "/usr/lib/python2.6/site-packages/mysql/connector/connection.py", line 108, in __init__
    self.connect(**kwargs)
  File "/usr/lib/python2.6/site-packages/mysql/connector/connection.py", line 356, in connect
    self._open_connection()
  File "/usr/lib/python2.6/site-packages/mysql/connector/connection.py", line 319, in _open_connection
    self._socket.open_connection()
  File "/usr/lib/python2.6/site-packages/mysql/connector/network.py", line 393, in open_connection
    errno=2003, values=(self.server_host, msg))
InterfaceError: 2003: Can't connect to MySQL server on 'localhost' (111)
[2013-08-18 20:01:01,461]CRITICAL: The process is terminated with an exception.
Traceback (most recent call last):
  File "/home/cdnlab-gnp/gnp-deploy/obtain_ipaddr.py", line 170, in <module>
    autocommit=True)
  File "/usr/lib/python2.6/site-packages/mysql/connector/__init__.py", line 44, in Connect
    return MySQLConnection(*args, **kwargs)
  File "/usr/lib/python2.6/site-packages/mysql/connector/connection.py", line 108, in __init__
    self.connect(**kwargs)
  File "/usr/lib/python2.6/site-packages/mysql/connector/connection.py", line 356, in connect
    self._open_connection()
  File "/usr/lib/python2.6/site-packages/mysql/connector/connection.py", line 319, in _open_connection
    self._socket.open_connection()
  File "/usr/lib/python2.6/site-packages/mysql/connector/network.py", line 393, in open_connection
    errno=2003, values=(self.server_host, msg))
InterfaceError: 2003: Can't connect to MySQL server on 'localhost' (111)
[2013-08-18 21:01:01,102]CRITICAL: The process is terminated with an exception.
Traceback (most recent call last):
  File "/home/cdnlab-gnp/gnp-deploy/obtain_ipaddr.py", line 170, in <module>
    autocommit=True)
  File "/usr/lib/python2.6/site-packages/mysql/connector/__init__.py", line 44, in Connect
    return MySQLConnection(*args, **kwargs)
  File "/usr/lib/python2.6/site-packages/mysql/connector/connection.py", line 108, in __init__
    self.connect(**kwargs)
  File "/usr/lib/python2.6/site-packages/mysql/connector/connection.py", line 356, in connect
    self._open_connection()
  File "/usr/lib/python2.6/site-packages/mysql/connector/connection.py", line 319, in _open_connection
    self._socket.open_connection()
  File "/usr/lib/python2.6/site-packages/mysql/connector/network.py", line 393, in open_connection
    errno=2003, values=(self.server_host, msg))
InterfaceError: 2003: Can't connect to MySQL server on 'localhost' (111)
[2013-08-18 22:01:01,379]CRITICAL: The process is terminated with an exception.
Traceback (most recent call last):
  File "/home/cdnlab-gnp/gnp-deploy/obtain_ipaddr.py", line 170, in <module>
    autocommit=True)
  File "/usr/lib/python2.6/site-packages/mysql/connector/__init__.py", line 44, in Connect
    return MySQLConnection(*args, **kwargs)
  File "/usr/lib/python2.6/site-packages/mysql/connector/connection.py", line 108, in __init__
    self.connect(**kwargs)
  File "/usr/lib/python2.6/site-packages/mysql/connector/connection.py", line 356, in connect
    self._open_connection()
  File "/usr/lib/python2.6/site-packages/mysql/connector/connection.py", line 319, in _open_connection
    self._socket.open_connection()
  File "/usr/lib/python2.6/site-packages/mysql/connector/network.py", line 393, in open_connection
    errno=2003, values=(self.server_host, msg))
InterfaceError: 2003: Can't connect to MySQL server on 'localhost' (111)
[2013-08-18 23:01:01,404]CRITICAL: The process is terminated with an exception.
Traceback (most recent call last):
  File "/home/cdnlab-gnp/gnp-deploy/obtain_ipaddr.py", line 170, in <module>
    autocommit=True)
  File "/usr/lib/python2.6/site-packages/mysql/connector/__init__.py", line 44, in Connect
    return MySQLConnection(*args, **kwargs)
  File "/usr/lib/python2.6/site-packages/mysql/connector/connection.py", line 108, in __init__
    self.connect(**kwargs)
  File "/usr/lib/python2.6/site-packages/mysql/connector/connection.py", line 356, in connect
    self._open_connection()
  File "/usr/lib/python2.6/site-packages/mysql/connector/connection.py", line 319, in _open_connection
    self._socket.open_connection()
  File "/usr/lib/python2.6/site-packages/mysql/connector/network.py", line 393, in open_connection
    errno=2003, values=(self.server_host, msg))
InterfaceError: 2003: Can't connect to MySQL server on 'localhost' (111)
[2013-08-19 00:01:01,851]CRITICAL: The process is terminated with an exception.
Traceback (most recent call last):
  File "/home/cdnlab-gnp/gnp-deploy/obtain_ipaddr.py", line 170, in <module>
    autocommit=True)
  File "/usr/lib/python2.6/site-packages/mysql/connector/__init__.py", line 44, in Connect
    return MySQLConnection(*args, **kwargs)
  File "/usr/lib/python2.6/site-packages/mysql/connector/connection.py", line 108, in __init__
    self.connect(**kwargs)
  File "/usr/lib/python2.6/site-packages/mysql/connector/connection.py", line 356, in connect
    self._open_connection()
  File "/usr/lib/python2.6/site-packages/mysql/connector/connection.py", line 319, in _open_connection
    self._socket.open_connection()
  File "/usr/lib/python2.6/site-packages/mysql/connector/network.py", line 393, in open_connection
    errno=2003, values=(self.server_host, msg))
InterfaceError: 2003: Can't connect to MySQL server on 'localhost' (111)
[2013-08-19 01:01:01,124]CRITICAL: The process is terminated with an exception.
Traceback (most recent call last):
  File "/home/cdnlab-gnp/gnp-deploy/obtain_ipaddr.py", line 170, in <module>
    autocommit=True)
  File "/usr/lib/python2.6/site-packages/mysql/connector/__init__.py", line 44, in Connect
    return MySQLConnection(*args, **kwargs)
  File "/usr/lib/python2.6/site-packages/mysql/connector/connection.py", line 108, in __init__
    self.connect(**kwargs)
  File "/usr/lib/python2.6/site-packages/mysql/connector/connection.py", line 356, in connect
    self._open_connection()
  File "/usr/lib/python2.6/site-packages/mysql/connector/connection.py", line 319, in _open_connection
    self._socket.open_connection()
  File "/usr/lib/python2.6/site-packages/mysql/connector/network.py", line 393, in open_connection
    errno=2003, values=(self.server_host, msg))
InterfaceError: 2003: Can't connect to MySQL server on 'localhost' (111)
[2013-08-19 02:01:01,531]CRITICAL: The process is terminated with an exception.
Traceback (most recent call last):
  File "/home/cdnlab-gnp/gnp-deploy/obtain_ipaddr.py", line 170, in <module>
    autocommit=True)
  File "/usr/lib/python2.6/site-packages/mysql/connector/__init__.py", line 44, in Connect
    return MySQLConnection(*args, **kwargs)
  File "/usr/lib/python2.6/site-packages/mysql/connector/connection.py", line 108, in __init__
    self.connect(**kwargs)
  File "/usr/lib/python2.6/site-packages/mysql/connector/connection.py", line 356, in connect
    self._open_connection()
  File "/usr/lib/python2.6/site-packages/mysql/connector/connection.py", line 319, in _open_connection
    self._socket.open_connection()
  File "/usr/lib/python2.6/site-packages/mysql/connector/network.py", line 393, in open_connection
    errno=2003, values=(self.server_host, msg))
InterfaceError: 2003: Can't connect to MySQL server on 'localhost' (111)
[2013-08-19 03:01:02,032]CRITICAL: The process is terminated with an exception.
Traceback (most recent call last):
  File "/home/cdnlab-gnp/gnp-deploy/obtain_ipaddr.py", line 170, in <module>
    autocommit=True)
  File "/usr/lib/python2.6/site-packages/mysql/connector/__init__.py", line 44, in Connect
    return MySQLConnection(*args, **kwargs)
  File "/usr/lib/python2.6/site-packages/mysql/connector/connection.py", line 108, in __init__
    self.connect(**kwargs)
  File "/usr/lib/python2.6/site-packages/mysql/connector/connection.py", line 356, in connect
    self._open_connection()
  File "/usr/lib/python2.6/site-packages/mysql/connector/connection.py", line 319, in _open_connection
    self._socket.open_connection()
  File "/usr/lib/python2.6/site-packages/mysql/connector/network.py", line 393, in open_connection
    errno=2003, values=(self.server_host, msg))
InterfaceError: 2003: Can't connect to MySQL server on 'localhost' (111)
[2013-08-19 04:01:01,879]CRITICAL: The process is terminated with an exception.
Traceback (most recent call last):
  File "/home/cdnlab-gnp/gnp-deploy/obtain_ipaddr.py", line 170, in <module>
    autocommit=True)
  File "/usr/lib/python2.6/site-packages/mysql/connector/__init__.py", line 44, in Connect
    return MySQLConnection(*args, **kwargs)
  File "/usr/lib/python2.6/site-packages/mysql/connector/connection.py", line 108, in __init__
    self.connect(**kwargs)
  File "/usr/lib/python2.6/site-packages/mysql/connector/connection.py", line 356, in connect
    self._open_connection()
  File "/usr/lib/python2.6/site-packages/mysql/connector/connection.py", line 319, in _open_connection
    self._socket.open_connection()
  File "/usr/lib/python2.6/site-packages/mysql/connector/network.py", line 393, in open_connection
    errno=2003, values=(self.server_host, msg))
InterfaceError: 2003: Can't connect to MySQL server on 'localhost' (111)
[2013-08-19 05:01:01,476]CRITICAL: The process is terminated with an exception.
Traceback (most recent call last):
  File "/home/cdnlab-gnp/gnp-deploy/obtain_ipaddr.py", line 170, in <module>
    autocommit=True)
  File "/usr/lib/python2.6/site-packages/mysql/connector/__init__.py", line 44, in Connect
    return MySQLConnection(*args, **kwargs)
  File "/usr/lib/python2.6/site-packages/mysql/connector/connection.py", line 108, in __init__
    self.connect(**kwargs)
  File "/usr/lib/python2.6/site-packages/mysql/connector/connection.py", line 356, in connect
    self._open_connection()
  File "/usr/lib/python2.6/site-packages/mysql/connector/connection.py", line 319, in _open_connection
    self._socket.open_connection()
  File "/usr/lib/python2.6/site-packages/mysql/connector/network.py", line 393, in open_connection
    errno=2003, values=(self.server_host, msg))
InterfaceError: 2003: Can't connect to MySQL server on 'localhost' (111)
[2013-08-19 06:01:01,441]CRITICAL: The process is terminated with an exception.
Traceback (most recent call last):
  File "/home/cdnlab-gnp/gnp-deploy/obtain_ipaddr.py", line 170, in <module>
    autocommit=True)
  File "/usr/lib/python2.6/site-packages/mysql/connector/__init__.py", line 44, in Connect
    return MySQLConnection(*args, **kwargs)
  File "/usr/lib/python2.6/site-packages/mysql/connector/connection.py", line 108, in __init__
    self.connect(**kwargs)
  File "/usr/lib/python2.6/site-packages/mysql/connector/connection.py", line 356, in connect
    self._open_connection()
  File "/usr/lib/python2.6/site-packages/mysql/connector/connection.py", line 319, in _open_connection
    self._socket.open_connection()
  File "/usr/lib/python2.6/site-packages/mysql/connector/network.py", line 393, in open_connection
    errno=2003, values=(self.server_host, msg))
InterfaceError: 2003: Can't connect to MySQL server on 'localhost' (111)
[2013-08-19 07:01:01,656]CRITICAL: The process is terminated with an exception.
Traceback (most recent call last):
  File "/home/cdnlab-gnp/gnp-deploy/obtain_ipaddr.py", line 170, in <module>
    autocommit=True)
  File "/usr/lib/python2.6/site-packages/mysql/connector/__init__.py", line 44, in Connect
    return MySQLConnection(*args, **kwargs)
  File "/usr/lib/python2.6/site-packages/mysql/connector/connection.py", line 108, in __init__
    self.connect(**kwargs)
  File "/usr/lib/python2.6/site-packages/mysql/connector/connection.py", line 356, in connect
    self._open_connection()
  File "/usr/lib/python2.6/site-packages/mysql/connector/connection.py", line 319, in _open_connection
    self._socket.open_connection()
  File "/usr/lib/python2.6/site-packages/mysql/connector/network.py", line 393, in open_connection
    errno=2003, values=(self.server_host, msg))
InterfaceError: 2003: Can't connect to MySQL server on 'localhost' (111)
[2013-08-19 08:01:02,090]CRITICAL: The process is terminated with an exception.
Traceback (most recent call last):
  File "/home/cdnlab-gnp/gnp-deploy/obtain_ipaddr.py", line 170, in <module>
    autocommit=True)
  File "/usr/lib/python2.6/site-packages/mysql/connector/__init__.py", line 44, in Connect
    return MySQLConnection(*args, **kwargs)
  File "/usr/lib/python2.6/site-packages/mysql/connector/connection.py", line 108, in __init__
    self.connect(**kwargs)
  File "/usr/lib/python2.6/site-packages/mysql/connector/connection.py", line 356, in connect
    self._open_connection()
  File "/usr/lib/python2.6/site-packages/mysql/connector/connection.py", line 319, in _open_connection
    self._socket.open_connection()
  File "/usr/lib/python2.6/site-packages/mysql/connector/network.py", line 393, in open_connection
    errno=2003, values=(self.server_host, msg))
InterfaceError: 2003: Can't connect to MySQL server on 'localhost' (111)
[2013-08-19 09:01:01,236]CRITICAL: The process is terminated with an exception.
Traceback (most recent call last):
  File "/home/cdnlab-gnp/gnp-deploy/obtain_ipaddr.py", line 170, in <module>
    autocommit=True)
  File "/usr/lib/python2.6/site-packages/mysql/connector/__init__.py", line 44, in Connect
    return MySQLConnection(*args, **kwargs)
  File "/usr/lib/python2.6/site-packages/mysql/connector/connection.py", line 108, in __init__
    self.connect(**kwargs)
  File "/usr/lib/python2.6/site-packages/mysql/connector/connection.py", line 356, in connect
    self._open_connection()
  File "/usr/lib/python2.6/site-packages/mysql/connector/connection.py", line 319, in _open_connection
    self._socket.open_connection()
  File "/usr/lib/python2.6/site-packages/mysql/connector/network.py", line 393, in open_connection
    errno=2003, values=(self.server_host, msg))
InterfaceError: 2003: Can't connect to MySQL server on 'localhost' (111)
[2013-08-19 10:01:01,144]CRITICAL: The process is terminated with an exception.
Traceback (most recent call last):
  File "/home/cdnlab-gnp/gnp-deploy/obtain_ipaddr.py", line 170, in <module>
    autocommit=True)
  File "/usr/lib/python2.6/site-packages/mysql/connector/__init__.py", line 44, in Connect
    return MySQLConnection(*args, **kwargs)
  File "/usr/lib/python2.6/site-packages/mysql/connector/connection.py", line 108, in __init__
    self.connect(**kwargs)
  File "/usr/lib/python2.6/site-packages/mysql/connector/connection.py", line 356, in connect
    self._open_connection()
  File "/usr/lib/python2.6/site-packages/mysql/connector/connection.py", line 319, in _open_connection
    self._socket.open_connection()
  File "/usr/lib/python2.6/site-packages/mysql/connector/network.py", line 393, in open_connection
    errno=2003, values=(self.server_host, msg))
InterfaceError: 2003: Can't connect to MySQL server on 'localhost' (111)
[2013-08-19 11:01:01,260]CRITICAL: The process is terminated with an exception.
Traceback (most recent call last):
  File "/home/cdnlab-gnp/gnp-deploy/obtain_ipaddr.py", line 170, in <module>
    autocommit=True)
  File "/usr/lib/python2.6/site-packages/mysql/connector/__init__.py", line 44, in Connect
    return MySQLConnection(*args, **kwargs)
  File "/usr/lib/python2.6/site-packages/mysql/connector/connection.py", line 108, in __init__
    self.connect(**kwargs)
  File "/usr/lib/python2.6/site-packages/mysql/connector/connection.py", line 356, in connect
    self._open_connection()
  File "/usr/lib/python2.6/site-packages/mysql/connector/connection.py", line 319, in _open_connection
    self._socket.open_connection()
  File "/usr/lib/python2.6/site-packages/mysql/connector/network.py", line 393, in open_connection
    errno=2003, values=(self.server_host, msg))
InterfaceError: 2003: Can't connect to MySQL server on 'localhost' (111)
[2013-08-19 12:01:01,713]CRITICAL: The process is terminated with an exception.
Traceback (most recent call last):
  File "/home/cdnlab-gnp/gnp-deploy/obtain_ipaddr.py", line 170, in <module>
    autocommit=True)
  File "/usr/lib/python2.6/site-packages/mysql/connector/__init__.py", line 44, in Connect
    return MySQLConnection(*args, **kwargs)
  File "/usr/lib/python2.6/site-packages/mysql/connector/connection.py", line 108, in __init__
    self.connect(**kwargs)
  File "/usr/lib/python2.6/site-packages/mysql/connector/connection.py", line 356, in connect
    self._open_connection()
  File "/usr/lib/python2.6/site-packages/mysql/connector/connection.py", line 319, in _open_connection
    self._socket.open_connection()
  File "/usr/lib/python2.6/site-packages/mysql/connector/network.py", line 393, in open_connection
    errno=2003, values=(self.server_host, msg))
InterfaceError: 2003: Can't connect to MySQL server on 'localhost' (111)
[2013-08-19 13:01:01,196]CRITICAL: The process is terminated with an exception.
Traceback (most recent call last):
  File "/home/cdnlab-gnp/gnp-deploy/obtain_ipaddr.py", line 170, in <module>
    autocommit=True)
  File "/usr/lib/python2.6/site-packages/mysql/connector/__init__.py", line 44, in Connect
    return MySQLConnection(*args, **kwargs)
  File "/usr/lib/python2.6/site-packages/mysql/connector/connection.py", line 108, in __init__
    self.connect(**kwargs)
  File "/usr/lib/python2.6/site-packages/mysql/connector/connection.py", line 356, in connect
    self._open_connection()
  File "/usr/lib/python2.6/site-packages/mysql/connector/connection.py", line 319, in _open_connection
    self._socket.open_connection()
  File "/usr/lib/python2.6/site-packages/mysql/connector/network.py", line 393, in open_connection
    errno=2003, values=(self.server_host, msg))
InterfaceError: 2003: Can't connect to MySQL server on 'localhost' (111)
[2013-08-19 14:01:01,191]CRITICAL: The process is terminated with an exception.
Traceback (most recent call last):
  File "/home/cdnlab-gnp/gnp-deploy/obtain_ipaddr.py", line 170, in <module>
    autocommit=True)
  File "/usr/lib/python2.6/site-packages/mysql/connector/__init__.py", line 44, in Connect
    return MySQLConnection(*args, **kwargs)
  File "/usr/lib/python2.6/site-packages/mysql/connector/connection.py", line 108, in __init__
    self.connect(**kwargs)
  File "/usr/lib/python2.6/site-packages/mysql/connector/connection.py", line 356, in connect
    self._open_connection()
  File "/usr/lib/python2.6/site-packages/mysql/connector/connection.py", line 319, in _open_connection
    self._socket.open_connection()
  File "/usr/lib/python2.6/site-packages/mysql/connector/network.py", line 393, in open_connection
    errno=2003, values=(self.server_host, msg))
InterfaceError: 2003: Can't connect to MySQL server on 'localhost' (111)
[2013-08-19 15:01:01,132]CRITICAL: The process is terminated with an exception.
Traceback (most recent call last):
  File "/home/cdnlab-gnp/gnp-deploy/obtain_ipaddr.py", line 170, in <module>
    autocommit=True)
  File "/usr/lib/python2.6/site-packages/mysql/connector/__init__.py", line 44, in Connect
    return MySQLConnection(*args, **kwargs)
  File "/usr/lib/python2.6/site-packages/mysql/connector/connection.py", line 108, in __init__
    self.connect(**kwargs)
  File "/usr/lib/python2.6/site-packages/mysql/connector/connection.py", line 356, in connect
    self._open_connection()
  File "/usr/lib/python2.6/site-packages/mysql/connector/connection.py", line 319, in _open_connection
    self._socket.open_connection()
  File "/usr/lib/python2.6/site-packages/mysql/connector/network.py", line 393, in open_connection
    errno=2003, values=(self.server_host, msg))
InterfaceError: 2003: Can't connect to MySQL server on 'localhost' (111)
[2013-08-19 16:01:01,880]CRITICAL: The process is terminated with an exception.
Traceback (most recent call last):
  File "/home/cdnlab-gnp/gnp-deploy/obtain_ipaddr.py", line 170, in <module>
    autocommit=True)
  File "/usr/lib/python2.6/site-packages/mysql/connector/__init__.py", line 44, in Connect
    return MySQLConnection(*args, **kwargs)
  File "/usr/lib/python2.6/site-packages/mysql/connector/connection.py", line 108, in __init__
    self.connect(**kwargs)
  File "/usr/lib/python2.6/site-packages/mysql/connector/connection.py", line 356, in connect
    self._open_connection()
  File "/usr/lib/python2.6/site-packages/mysql/connector/connection.py", line 319, in _open_connection
    self._socket.open_connection()
  File "/usr/lib/python2.6/site-packages/mysql/connector/network.py", line 393, in open_connection
    errno=2003, values=(self.server_host, msg))
InterfaceError: 2003: Can't connect to MySQL server on 'localhost' (111)
[2013-08-19 17:01:02,067]CRITICAL: The process is terminated with an exception.
Traceback (most recent call last):
  File "/home/cdnlab-gnp/gnp-deploy/obtain_ipaddr.py", line 170, in <module>
    autocommit=True)
  File "/usr/lib/python2.6/site-packages/mysql/connector/__init__.py", line 44, in Connect
    return MySQLConnection(*args, **kwargs)
  File "/usr/lib/python2.6/site-packages/mysql/connector/connection.py", line 108, in __init__
    self.connect(**kwargs)
  File "/usr/lib/python2.6/site-packages/mysql/connector/connection.py", line 356, in connect
    self._open_connection()
  File "/usr/lib/python2.6/site-packages/mysql/connector/connection.py", line 319, in _open_connection
    self._socket.open_connection()
  File "/usr/lib/python2.6/site-packages/mysql/connector/network.py", line 393, in open_connection
    errno=2003, values=(self.server_host, msg))
InterfaceError: 2003: Can't connect to MySQL server on 'localhost' (111)
[2013-08-19 18:01:02,047]CRITICAL: The process is terminated with an exception.
Traceback (most recent call last):
  File "/home/cdnlab-gnp/gnp-deploy/obtain_ipaddr.py", line 170, in <module>
    autocommit=True)
  File "/usr/lib/python2.6/site-packages/mysql/connector/__init__.py", line 44, in Connect
    return MySQLConnection(*args, **kwargs)
  File "/usr/lib/python2.6/site-packages/mysql/connector/connection.py", line 108, in __init__
    self.connect(**kwargs)
  File "/usr/lib/python2.6/site-packages/mysql/connector/connection.py", line 356, in connect
    self._open_connection()
  File "/usr/lib/python2.6/site-packages/mysql/connector/connection.py", line 319, in _open_connection
    self._socket.open_connection()
  File "/usr/lib/python2.6/site-packages/mysql/connector/network.py", line 393, in open_connection
    errno=2003, values=(self.server_host, msg))
InterfaceError: 2003: Can't connect to MySQL server on 'localhost' (111)
[2013-08-19 19:01:01,699]CRITICAL: The process is terminated with an exception.
Traceback (most recent call last):
  File "/home/cdnlab-gnp/gnp-deploy/obtain_ipaddr.py", line 170, in <module>
    autocommit=True)
  File "/usr/lib/python2.6/site-packages/mysql/connector/__init__.py", line 44, in Connect
    return MySQLConnection(*args, **kwargs)
  File "/usr/lib/python2.6/site-packages/mysql/connector/connection.py", line 108, in __init__
    self.connect(**kwargs)
  File "/usr/lib/python2.6/site-packages/mysql/connector/connection.py", line 356, in connect
    self._open_connection()
  File "/usr/lib/python2.6/site-packages/mysql/connector/connection.py", line 319, in _open_connection
    self._socket.open_connection()
  File "/usr/lib/python2.6/site-packages/mysql/connector/network.py", line 393, in open_connection
    errno=2003, values=(self.server_host, msg))
InterfaceError: 2003: Can't connect to MySQL server on 'localhost' (111)
[2013-08-19 20:01:01,388]CRITICAL: The process is terminated with an exception.
Traceback (most recent call last):
  File "/home/cdnlab-gnp/gnp-deploy/obtain_ipaddr.py", line 170, in <module>
    autocommit=True)
  File "/usr/lib/python2.6/site-packages/mysql/connector/__init__.py", line 44, in Connect
    return MySQLConnection(*args, **kwargs)
  File "/usr/lib/python2.6/site-packages/mysql/connector/connection.py", line 108, in __init__
    self.connect(**kwargs)
  File "/usr/lib/python2.6/site-packages/mysql/connector/connection.py", line 356, in connect
    self._open_connection()
  File "/usr/lib/python2.6/site-packages/mysql/connector/connection.py", line 319, in _open_connection
    self._socket.open_connection()
  File "/usr/lib/python2.6/site-packages/mysql/connector/network.py", line 393, in open_connection
    errno=2003, values=(self.server_host, msg))
InterfaceError: 2003: Can't connect to MySQL server on 'localhost' (111)
[2013-08-19 21:01:01,162]CRITICAL: The process is terminated with an exception.
Traceback (most recent call last):
  File "/home/cdnlab-gnp/gnp-deploy/obtain_ipaddr.py", line 170, in <module>
    autocommit=True)
  File "/usr/lib/python2.6/site-packages/mysql/connector/__init__.py", line 44, in Connect
    return MySQLConnection(*args, **kwargs)
  File "/usr/lib/python2.6/site-packages/mysql/connector/connection.py", line 108, in __init__
    self.connect(**kwargs)
  File "/usr/lib/python2.6/site-packages/mysql/connector/connection.py", line 356, in connect
    self._open_connection()
  File "/usr/lib/python2.6/site-packages/mysql/connector/connection.py", line 319, in _open_connection
    self._socket.open_connection()
  File "/usr/lib/python2.6/site-packages/mysql/connector/network.py", line 393, in open_connection
    errno=2003, values=(self.server_host, msg))
InterfaceError: 2003: Can't connect to MySQL server on 'localhost' (111)
[2013-08-19 22:01:01,828]CRITICAL: The process is terminated with an exception.
Traceback (most recent call last):
  File "/home/cdnlab-gnp/gnp-deploy/obtain_ipaddr.py", line 170, in <module>
    autocommit=True)
  File "/usr/lib/python2.6/site-packages/mysql/connector/__init__.py", line 44, in Connect
    return MySQLConnection(*args, **kwargs)
  File "/usr/lib/python2.6/site-packages/mysql/connector/connection.py", line 108, in __init__
    self.connect(**kwargs)
  File "/usr/lib/python2.6/site-packages/mysql/connector/connection.py", line 356, in connect
    self._open_connection()
  File "/usr/lib/python2.6/site-packages/mysql/connector/connection.py", line 319, in _open_connection
    self._socket.open_connection()
  File "/usr/lib/python2.6/site-packages/mysql/connector/network.py", line 393, in open_connection
    errno=2003, values=(self.server_host, msg))
InterfaceError: 2003: Can't connect to MySQL server on 'localhost' (111)
[2013-08-19 23:01:01,962]CRITICAL: The process is terminated with an exception.
Traceback (most recent call last):
  File "/home/cdnlab-gnp/gnp-deploy/obtain_ipaddr.py", line 170, in <module>
    autocommit=True)
  File "/usr/lib/python2.6/site-packages/mysql/connector/__init__.py", line 44, in Connect
    return MySQLConnection(*args, **kwargs)
  File "/usr/lib/python2.6/site-packages/mysql/connector/connection.py", line 108, in __init__
    self.connect(**kwargs)
  File "/usr/lib/python2.6/site-packages/mysql/connector/connection.py", line 356, in connect
    self._open_connection()
  File "/usr/lib/python2.6/site-packages/mysql/connector/connection.py", line 319, in _open_connection
    self._socket.open_connection()
  File "/usr/lib/python2.6/site-packages/mysql/connector/network.py", line 393, in open_connection
    errno=2003, values=(self.server_host, msg))
InterfaceError: 2003: Can't connect to MySQL server on 'localhost' (111)
[2013-08-20 00:01:02,006]CRITICAL: The process is terminated with an exception.
Traceback (most recent call last):
  File "/home/cdnlab-gnp/gnp-deploy/obtain_ipaddr.py", line 170, in <module>
    autocommit=True)
  File "/usr/lib/python2.6/site-packages/mysql/connector/__init__.py", line 44, in Connect
    return MySQLConnection(*args, **kwargs)
  File "/usr/lib/python2.6/site-packages/mysql/connector/connection.py", line 108, in __init__
    self.connect(**kwargs)
  File "/usr/lib/python2.6/site-packages/mysql/connector/connection.py", line 356, in connect
    self._open_connection()
  File "/usr/lib/python2.6/site-packages/mysql/connector/connection.py", line 319, in _open_connection
    self._socket.open_connection()
  File "/usr/lib/python2.6/site-packages/mysql/connector/network.py", line 393, in open_connection
    errno=2003, values=(self.server_host, msg))
InterfaceError: 2003: Can't connect to MySQL server on 'localhost' (111)
[2013-08-20 01:01:01,520]CRITICAL: The process is terminated with an exception.
Traceback (most recent call last):
  File "/home/cdnlab-gnp/gnp-deploy/obtain_ipaddr.py", line 170, in <module>
    autocommit=True)
  File "/usr/lib/python2.6/site-packages/mysql/connector/__init__.py", line 44, in Connect
    return MySQLConnection(*args, **kwargs)
  File "/usr/lib/python2.6/site-packages/mysql/connector/connection.py", line 108, in __init__
    self.connect(**kwargs)
  File "/usr/lib/python2.6/site-packages/mysql/connector/connection.py", line 356, in connect
    self._open_connection()
  File "/usr/lib/python2.6/site-packages/mysql/connector/connection.py", line 319, in _open_connection
    self._socket.open_connection()
  File "/usr/lib/python2.6/site-packages/mysql/connector/network.py", line 393, in open_connection
    errno=2003, values=(self.server_host, msg))
InterfaceError: 2003: Can't connect to MySQL server on 'localhost' (111)
