[2013-07-31 12:33:44,461] The process is done normally.
[2013-07-31 14:04:21,165] The process is done normally.
[2013-07-31 16:04:22,656] The process is done normally.
[2013-07-31 18:04:21,450] The process is done normally.
[2013-07-31 20:04:21,969] The process is done normally.
[2013-07-31 22:04:21,447] The process is done normally.
[2013-08-01 00:01:04,270] The process is done normally.
[2013-08-01 02:01:04,537] The process is done normally.
[2013-08-01 04:01:04,985] The process is done normally.
[2013-08-01 06:01:04,975] The process is done normally.
[2013-08-01 08:01:04,477] The process is done normally.
[2013-08-01 10:01:04,820] The process is done normally.
[2013-08-03 04:01:01,833] Traceback (most recent call last):
  File "/home/cdnlab-gnp/gnp-deploy/obtain_ipaddr.py", line 164, in <module>
    autocommit=True)
  File "/usr/lib/python2.6/site-packages/mysql/connector/__init__.py", line 44, in Connect
    return MySQLConnection(*args, **kwargs)
  File "/usr/lib/python2.6/site-packages/mysql/connector/connection.py", line 108, in __init__
    self.connect(**kwargs)
  File "/usr/lib/python2.6/site-packages/mysql/connector/connection.py", line 356, in connect
    self._open_connection()
  File "/usr/lib/python2.6/site-packages/mysql/connector/connection.py", line 319, in _open_connection
    self._socket.open_connection()
  File "/usr/lib/python2.6/site-packages/mysql/connector/network.py", line 393, in open_connection
    errno=2003, values=(self.server_host, msg))
InterfaceError: 2003: Can't connect to MySQL server on 'localhost' (111)
Traceback (most recent call last):
  File "/home/cdnlab-gnp/gnp-deploy/obtain_ipaddr.py", line 164, in <module>
    autocommit=True)
  File "/usr/lib/python2.6/site-packages/mysql/connector/__init__.py", line 44, in Connect
    return MySQLConnection(*args, **kwargs)
  File "/usr/lib/python2.6/site-packages/mysql/connector/connection.py", line 108, in __init__
    self.connect(**kwargs)
  File "/usr/lib/python2.6/site-packages/mysql/connector/connection.py", line 356, in connect
    self._open_connection()
  File "/usr/lib/python2.6/site-packages/mysql/connector/connection.py", line 319, in _open_connection
    self._socket.open_connection()
  File "/usr/lib/python2.6/site-packages/mysql/connector/network.py", line 393, in open_connection
    errno=2003, values=(self.server_host, msg))
InterfaceError: 2003: Can't connect to MySQL server on 'localhost' (111)
[2013-08-03 04:01:01,833] The process is terminated with an exception.
[2013-08-03 06:01:01,806] Traceback (most recent call last):
  File "/home/cdnlab-gnp/gnp-deploy/obtain_ipaddr.py", line 164, in <module>
    autocommit=True)
  File "/usr/lib/python2.6/site-packages/mysql/connector/__init__.py", line 44, in Connect
    return MySQLConnection(*args, **kwargs)
  File "/usr/lib/python2.6/site-packages/mysql/connector/connection.py", line 108, in __init__
    self.connect(**kwargs)
  File "/usr/lib/python2.6/site-packages/mysql/connector/connection.py", line 356, in connect
    self._open_connection()
  File "/usr/lib/python2.6/site-packages/mysql/connector/connection.py", line 319, in _open_connection
    self._socket.open_connection()
  File "/usr/lib/python2.6/site-packages/mysql/connector/network.py", line 393, in open_connection
    errno=2003, values=(self.server_host, msg))
InterfaceError: 2003: Can't connect to MySQL server on 'localhost' (111)
Traceback (most recent call last):
  File "/home/cdnlab-gnp/gnp-deploy/obtain_ipaddr.py", line 164, in <module>
    autocommit=True)
  File "/usr/lib/python2.6/site-packages/mysql/connector/__init__.py", line 44, in Connect
    return MySQLConnection(*args, **kwargs)
  File "/usr/lib/python2.6/site-packages/mysql/connector/connection.py", line 108, in __init__
    self.connect(**kwargs)
  File "/usr/lib/python2.6/site-packages/mysql/connector/connection.py", line 356, in connect
    self._open_connection()
  File "/usr/lib/python2.6/site-packages/mysql/connector/connection.py", line 319, in _open_connection
    self._socket.open_connection()
  File "/usr/lib/python2.6/site-packages/mysql/connector/network.py", line 393, in open_connection
    errno=2003, values=(self.server_host, msg))
InterfaceError: 2003: Can't connect to MySQL server on 'localhost' (111)
[2013-08-03 06:01:01,806] The process is terminated with an exception.
[2013-08-03 08:01:01,102] Traceback (most recent call last):
  File "/home/cdnlab-gnp/gnp-deploy/obtain_ipaddr.py", line 164, in <module>
    autocommit=True)
  File "/usr/lib/python2.6/site-packages/mysql/connector/__init__.py", line 44, in Connect
    return MySQLConnection(*args, **kwargs)
  File "/usr/lib/python2.6/site-packages/mysql/connector/connection.py", line 108, in __init__
    self.connect(**kwargs)
  File "/usr/lib/python2.6/site-packages/mysql/connector/connection.py", line 356, in connect
    self._open_connection()
  File "/usr/lib/python2.6/site-packages/mysql/connector/connection.py", line 319, in _open_connection
    self._socket.open_connection()
  File "/usr/lib/python2.6/site-packages/mysql/connector/network.py", line 393, in open_connection
    errno=2003, values=(self.server_host, msg))
InterfaceError: 2003: Can't connect to MySQL server on 'localhost' (111)
Traceback (most recent call last):
  File "/home/cdnlab-gnp/gnp-deploy/obtain_ipaddr.py", line 164, in <module>
    autocommit=True)
  File "/usr/lib/python2.6/site-packages/mysql/connector/__init__.py", line 44, in Connect
    return MySQLConnection(*args, **kwargs)
  File "/usr/lib/python2.6/site-packages/mysql/connector/connection.py", line 108, in __init__
    self.connect(**kwargs)
  File "/usr/lib/python2.6/site-packages/mysql/connector/connection.py", line 356, in connect
    self._open_connection()
  File "/usr/lib/python2.6/site-packages/mysql/connector/connection.py", line 319, in _open_connection
    self._socket.open_connection()
  File "/usr/lib/python2.6/site-packages/mysql/connector/network.py", line 393, in open_connection
    errno=2003, values=(self.server_host, msg))
InterfaceError: 2003: Can't connect to MySQL server on 'localhost' (111)
[2013-08-03 08:01:01,103] The process is terminated with an exception.
[2013-08-03 10:01:01,266] Traceback (most recent call last):
  File "/home/cdnlab-gnp/gnp-deploy/obtain_ipaddr.py", line 164, in <module>
    autocommit=True)
  File "/usr/lib/python2.6/site-packages/mysql/connector/__init__.py", line 44, in Connect
    return MySQLConnection(*args, **kwargs)
  File "/usr/lib/python2.6/site-packages/mysql/connector/connection.py", line 108, in __init__
    self.connect(**kwargs)
  File "/usr/lib/python2.6/site-packages/mysql/connector/connection.py", line 356, in connect
    self._open_connection()
  File "/usr/lib/python2.6/site-packages/mysql/connector/connection.py", line 319, in _open_connection
    self._socket.open_connection()
  File "/usr/lib/python2.6/site-packages/mysql/connector/network.py", line 393, in open_connection
    errno=2003, values=(self.server_host, msg))
InterfaceError: 2003: Can't connect to MySQL server on 'localhost' (111)
Traceback (most recent call last):
  File "/home/cdnlab-gnp/gnp-deploy/obtain_ipaddr.py", line 164, in <module>
    autocommit=True)
  File "/usr/lib/python2.6/site-packages/mysql/connector/__init__.py", line 44, in Connect
    return MySQLConnection(*args, **kwargs)
  File "/usr/lib/python2.6/site-packages/mysql/connector/connection.py", line 108, in __init__
    self.connect(**kwargs)
  File "/usr/lib/python2.6/site-packages/mysql/connector/connection.py", line 356, in connect
    self._open_connection()
  File "/usr/lib/python2.6/site-packages/mysql/connector/connection.py", line 319, in _open_connection
    self._socket.open_connection()
  File "/usr/lib/python2.6/site-packages/mysql/connector/network.py", line 393, in open_connection
    errno=2003, values=(self.server_host, msg))
InterfaceError: 2003: Can't connect to MySQL server on 'localhost' (111)
[2013-08-03 10:01:01,266] The process is terminated with an exception.
