[2013-08-07 13:01:31,748] Traceback (most recent call last):
  File "/home/cdnlab-gnp/gnp-deploy/nslookup_daemon.py", line 68, in nslookup
    ips = runCheck(i, domain)
  File "/home/cdnlab-gnp/gnp-deploy/nslookup_daemon.py", line 56, in runCheck
    result = socket.gethostbyname_ex(host)
herror: [Errno 2] Host name lookup failure
Traceback (most recent call last):
  File "/home/cdnlab-gnp/gnp-deploy/nslookup_daemon.py", line 68, in nslookup
    ips = runCheck(i, domain)
  File "/home/cdnlab-gnp/gnp-deploy/nslookup_daemon.py", line 56, in runCheck
    result = socket.gethostbyname_ex(host)
herror: [Errno 2] Host name lookup failure
[2013-08-07 13:01:31,748] [ 0] The job 62 is terminated with an exception.
[2013-08-07 13:01:51,812] Traceback (most recent call last):
  File "/home/cdnlab-gnp/gnp-deploy/nslookup_daemon.py", line 68, in nslookup
    ips = runCheck(i, domain)
  File "/home/cdnlab-gnp/gnp-deploy/nslookup_daemon.py", line 56, in runCheck
    result = socket.gethostbyname_ex(host)
herror: [Errno 2] Host name lookup failure
Traceback (most recent call last):
  File "/home/cdnlab-gnp/gnp-deploy/nslookup_daemon.py", line 68, in nslookup
    ips = runCheck(i, domain)
  File "/home/cdnlab-gnp/gnp-deploy/nslookup_daemon.py", line 56, in runCheck
    result = socket.gethostbyname_ex(host)
herror: [Errno 2] Host name lookup failure
[2013-08-07 13:01:51,812] [ 0] The job 110 is terminated with an exception.
[2013-08-07 13:39:51,255] Traceback (most recent call last):
  File "nslookup_daemon.py", line 133, in <module>
    queue.join()
  File "/usr/lib64/python2.6/Queue.py", line 82, in join
    self.all_tasks_done.wait()
  File "/usr/lib64/python2.6/threading.py", line 239, in wait
    waiter.acquire()
KeyboardInterrupt
Traceback (most recent call last):
  File "nslookup_daemon.py", line 133, in <module>
    queue.join()
  File "/usr/lib64/python2.6/Queue.py", line 82, in join
    self.all_tasks_done.wait()
  File "/usr/lib64/python2.6/threading.py", line 239, in wait
    waiter.acquire()
KeyboardInterrupt
[2013-08-07 13:39:51,256] The process is terminated with an exception.
